Workbook
Name all_in_one: 'All in One'!$A$1:$Z$77
Name cal_main: 主頁!$A$1:$W$46
Name 公社科: 選單!$I$2:$I$4
Name 丙類科目等級: 選單!$H$2:$H$8
Name 丙類選修科: 選單!$G$2:$G$8
Name 是否: 選單!$L$2:$L$3
Name 差: 選單!$F$7:$F$9
Name 差距ULM: 選單!$F$7:$F$9
Name 差距UML: 選單!$F$7:$F$9
Name 第一選修科: 選單!#REF!
Name 第二選修科: 選單!$D$2:$D$25
Name 第三選修科: 選單!$E$2:$E$25
Name 第四選修科: 選單!$F$2:$F$6
Name 等級: 選單!$A$2:$A$10
Name 數學延伸部份: 選單!#REF!
Name 數學延伸部份: 選單!#REF!
Name 選修科: 選單!#REF!

Sheet 開始

Sheet 主頁
B2: 2025 JUPAS 計分器 Ver 1.0.3 | H2: 只供參考 | K2: 請在下載後以電腦 Excel 開啟及使用。 (不能用Google Sheet)
K3: 若未能開啟/使用，則可嘗試「網頁版」: | P3: https://jupascal.github.io/
I4: 包括M1/2?
A5: 1. | B5: 請輸入你的成績: | C5: 以數字輸入成績? | D5: 否 | E5: 2. | F5: 分數概覽 (未計比重) | I5: 是 | K5: v1.0.3 Major UPDATE PATCH:
B6: 若開啟數字模式，則無法以下拉選單選擇分數 | D6: (0/1/2/3/4/5/6/7) | K6: 更正 UST & HKU 額外分數 計算錯漏
B7: 核心科目 | D7: 快速輸入 | F7: Best 4 | G7: =IF(計分版!E14=FALSE,計分版!E3,計分版!E8) -> 3e-09 | H7: 3C+1X | I7: =IF(計分版!E14=FALSE,計分版!E5,計分版!E12) -> 1.5e-09
B8: 中國語文 | C8: 請選擇等級 | F8: Best 5 | G8: =IF(計分版!E14=FALSE,計分版!E4,計分版!E9) -> 3.5e-09 | H8: 3C+2X | I8: =IF(計分版!E14=FALSE,計分版!E6,計分版!E13) -> 2.3e-09
B9: 英國語文 | C9: 請選擇等級 | K9: 請定期檢查更新 | T9: 一鍵前往
B10: 數學 | C10: 請選擇等級 | T10: All in One 超級計分器
B11: 公社科 | C11: 請選擇等級 | E11: 3. | F11: JUPAS排位 | I11: 此處顯示為2024年計分方式及數字 (分數已計比重)
B12: M1/2 | C12: 請選擇等級 | F12: 請輸入JUPAS編號 (e.g. JS4862) | I12: 請前往院校版面查看詳細註釋 | L12: 以百分比顯示差距? | N12: 是
O13: 2024年 | P13: Band A | Q13: 例如課程要求M1/2，若同學沒有修讀，就會變紅
B14: 選修科目 | G14: 院校 | H14: 學科 | I14: 計分方式 | J14: UQ | K14: Median | L14: LQ | M14: 你的分數 | N14: 學額 | O14: 取錄人數 | P14: 競爭人數 | Q14: 合乎基本入學要求?(並非入讀機率)
B15: 請選擇第一選修科 | C15: 請選擇等級 | E15: A1 | F15: JS4862 | G15: ='A123'!B16 -> CUHK | H15: ='A123'!D16 -> PSYCHOLOGY | I15: ='A123'!E16 -> Best 5 | J15: ='A123'!F16 -> 33.75 | K15: ='A123'!G16 -> 32.25 | L15: ='A123'!H16 -> 30.75 | M15: ='A123'!I16 -> 3.5e-09 | N15: ='A123'!J16 -> 56 | O15: ='A123'!K16 -> 60 | P15: ='A123'!L16 -> 5.7 | Q15: =IF('A123'!M16=0, "否",IF('A123'!M16=2,"或有額外要求",IF('A123'!M16=1,"是",""))) -> 否
A16: 按此 | B16: 請選擇第二選修科 | C16: 請選擇等級 | G16: ='A123'!C16 -> 心理學 | J16: =IF('A123'!A1=FALSE,'A123'!B5,'A123'!F5) -> -9.6428571e+09 | K16: =IF('A123'!A1=FALSE,'A123'!C5,'A123'!G5) -> -9.2142857e+09 | L16: =IF('A123'!A1=FALSE,'A123'!D5,'A123'!H5) -> -8.7857143e+09
A17: 展開 | B17: 請選擇第三選修科 | C17: 請選擇等級
A18: 選單 | B18: 請選擇第四選修科 | C18: 請選擇等級 | E18: A2 | G18: ='A123'!B17 | H18: ='A123'!D17 | I18: ='A123'!E17 | J18: ='A123'!F17 | K18: ='A123'!G17 | L18: ='A123'!H17 | M18: ='A123'!I17 | N18: ='A123'!J17 | O18: ='A123'!K17 | P18: ='A123'!L17 | Q18: =IF('A123'!M17=0, "否",IF('A123'!M17=2,"或有額外要求",IF('A123'!M17=1,"是",""))) | S18: 詳細資料及比重請前往院校分頁
B19: 請選擇語言科目 | C19: 請選擇等級 | G19: ='A123'!C17 | J19: =IF('A123'!A1=FALSE,'A123'!B7,'A123'!F7) | K19: =IF('A123'!A1=FALSE,'A123'!C7,'A123'!G7) | L19: =IF('A123'!A1=FALSE,'A123'!D7,'A123'!H7)
E21: A3 | G21: ='A123'!B18 | H21: ='A123'!D18 | I21: ='A123'!E18 | J21: ='A123'!F18 | K21: ='A123'!G18 | L21: ='A123'!H18 | M21: ='A123'!I18 | N21: ='A123'!J18 | O21: ='A123'!K18 | P21: ='A123'!L18 | Q21: =IF('A123'!M18=0, "否",IF('A123'!M18=2,"或有額外要求",IF('A123'!M18=1,"是","")))
B22: 每次使用前請檢查計分器是否為最新版本: | G22: ='A123'!C18 | J22: =IF('A123'!A1=FALSE,'A123'!B9,'A123'!F9) | K22: =IF('A123'!A1=FALSE,'A123'!C9,'A123'!G9) | L22: =IF('A123'!A1=FALSE,'A123'!D9,'A123'!H9) | N22: *= 合併學額 | P22: 競爭人數: 幾多人爭一個位
B23: https://drive.google.com/drive/folders/1PmyDrmQ2CumbWrqY7NRqa0Ol-M9VnkFz?usp=drive_link | D23: . | N23: (合併學額或有誤導成份，請以取錄人數為準)
B24: 歡迎各位有心人Debug,
B25: 請於Drive中Debug文件內註明Bug及其位置。
B26: O&A 及使用須知: | C26: https://docs.google.com/document/d/1tqdAzSbqYhME53ZdAFDEsJy-LOS5JIw8ViIbdLR9GI8/edit | E26: .
A28: 4. | B28: 重考扣分 (測試中) | F28: Previous Update Patch | O28: 使用須知 及 免責聲明
B29: (只需選擇今年有重新考試的科目) | D29: 2025年 | F29: v1.0.2 UPDATE PATCH:
B30: 核心科目 | D30: 重考? | F30: 更正 HKU JS6901,JS6119 比重計算錯漏 | O30: 此計算器提供的資料只作一般私人參考用途，並不可視為官方的詳盡及權威性的說明，亦不可取代專業諮詢。使用前請先留意最新版本，以及閱讀使用須知。 本人在編製此計算器時已力求審慎，盡可能確保計算器所提供的資料正確無誤、沒有錯漏，惟在個別情況下，這些資料仍可能與最新的情況有所不同。本人並不保證計算器內全部資料在各方面均絕對正確、毫無錯漏。任何使用此計算器人士，須自行承擔一切風險，對於因使用或依據此計算器內所提供的任何資料而引致的任何損失或損害，本人一概無須負上任何法律責任。
B31: 中國語文 | C31: =IF(計分版!$E$15=FALSE,IF(C8="請選擇等級","",C8),計分版!X7) | D31: 否
B32: 英國語文 | C32: =IF(計分版!$E$15=FALSE,IF(C9="請選擇等級","",C9),計分版!Y7) | D32: 否 | F32: v1.0.1 UPDATE PATCH:
B33: 數學 | C33: =IF(計分版!$E$15=FALSE,IF(C10="請選擇等級","",C10),計分版!Z7) | D33: 否 | F33: 更正 分數計算錯漏
B34: 公社科 ## | C34: =IF(計分版!$E$15=FALSE,IF(C11="請選擇等級","",C11),計分版!AA7) | D34: 否 | F34: 更正 首頁「快速輸入」排版設計
B35: M1/2 | C35: =IF(計分版!$E$15=FALSE,IF(C12="請選擇等級","",C12),計分版!AB7) | D35: 否
B37: 選修科目 | F37: Beta UPDATE PATCH:
B38: =IF(B15="請選擇第一選修科","",B15) | C38: =IF(計分版!$E$15=FALSE,IF(C15="請選擇等級","",C15),計分版!AC7) | D38: 否 | F38: 更新 2025年入學資料
B39: =IF(B16="請選擇第二選修科","",B16) | C39: =IF(計分版!$E$15=FALSE,IF(C16="請選擇等級","",C16),計分版!AD7) | D39: 否 | F39: 改善 排版設計
B40: =IF(B17="請選擇第三選修科","",B17) | C40: =IF(計分版!$E$15=FALSE,IF(C17="請選擇等級","",C17),計分版!AE7) | D40: 否 | F40: 更正 資料及計算錯漏
B41: =IF(B18="請選擇第四選修科","",B18) | C41: =IF(計分版!$E$15=FALSE,IF(C18="請選擇等級","",C18),計分版!AF7) | D41: 否
B42: =IF(B19="請選擇語言科目","",B19) | C42: =IF(計分版!$E$15=FALSE,IF(C19="請選擇等級","",C19),計分版!AG7) | D42: 否
B43: 目前只得 CUHK 及 HKU 有列明重考扣分
B44: 此功能只能計算 本年度DSE重考的情況，
...

Sheet A123
A1: =IF(主頁!N12="是",TRUE,FALSE) -> TRUE | B1: <-以百分比顯示差距 (Drop Menu) | E1: <- DO NOT DELETE, Data Validation on front page
A2: TRUE | B2: <-以百分比顯示差距 (Tickbox)
B3: 分數差距 | F3: 分數差距百分比
B4: UQ | C4: Median | D4: LQ | F4: UQ | G4: Median | H4: LQ
A5: A1 | B5: =IFERROR(主頁!M15-主頁!J15,"") -> -33.75 | C5: =IFERROR(主頁!M15-主頁!K15,"") -> -32.25 | D5: =IFERROR(主頁!M15-主頁!L15,"") -> -30.75 | F5: =IFERROR((主頁!$M$15-主頁!J15)/主頁!M15,"") -> -9.6428571e+09 | G5: =IFERROR((主頁!$M$15-主頁!K15)/主頁!$M$15,"") -> -9.2142857e+09 | H5: =IFERROR((主頁!$M$15-主頁!L15)/主頁!$M$15,"") -> -8.7857143e+09
A7: A2 | B7: =IFERROR(主頁!M18-主頁!J18,"") | C7: =IFERROR(主頁!M18-主頁!K18,"") | D7: =IFERROR(主頁!M18-主頁!L18,"") | F7: =IFERROR((主頁!$M$18-主頁!J18)/主頁!$M$18,"") | G7: =IFERROR((主頁!$M$18-主頁!K18)/主頁!$M$18,"") | H7: =IFERROR((主頁!$M$18-主頁!L18)/主頁!$M$18,"")
A9: A3 | B9: =IFERROR(主頁!M21-主頁!J21,"") | C9: =IFERROR(主頁!M21-主頁!K21,"") | D9: =IFERROR(主頁!M21-主頁!L21,"") | F9: =IFERROR((主頁!$M$21-主頁!J21)/主頁!$M$21,"") | G9: =IFERROR((主頁!$M$21-主頁!K21)/主頁!$M$21,"") | H9: =IFERROR((主頁!$M$21-主頁!L21)/主頁!$M$21,"")
A15: JUPAS No. | B15: 院校 | C15: 學科 | D15: 英文縮寫 | E15: 計分方式 | F15: UQ | G15: Median | H15: LQ | I15: 你的分數 | J15: 學額 | K15: 取錄人數 | L15: BandA競爭人數 | M15: 資格
A16: =主頁!F15 -> JS4862 | B16: =IFERROR(INDEX(B$21:B$502,MATCH($A16,$A$21:$A$502,0)),"") -> CUHK | C16: =IFERROR(INDEX(C$21:C$502,MATCH($A16,$A$21:$A$502,0)),"") -> 心理學 | D16: =IFERROR(INDEX(D$21:D$502,MATCH($A16,$A$21:$A$502,0)),"") -> PSYCHOLOGY | E16: =IFERROR(INDEX(E$21:E$502,MATCH($A16,$A$21:$A$502,0)),"") -> Best 5 | F16: =IFERROR(INDEX(F$21:F$502,MATCH($A16,$A$21:$A$502,0)),"") -> 33.75 | G16: =IFERROR(INDEX(G$21:G$502,MATCH($A16,$A$21:$A$502,0)),"") -> 32.25 | H16: =IFERROR(INDEX(H$21:H$502,MATCH($A16,$A$21:$A$502,0)),"") -> 30.75 | I16: =IFERROR(INDEX(I$21:I$502,MATCH($A16,$A$21:$A$502,0)),"") -> 3.5e-09 | ... M16: =IFERROR(INDEX(M$21:M$502,MATCH($A16,$A$21:$A$502,0)),"") -> 0
A17: =主頁!F18 -> 0 | B17: =IFERROR(INDEX(B$21:B$502,MATCH($A17,$A$21:$A$502,0)),"") | C17: =IFERROR(INDEX(C$21:C$502,MATCH($A17,$A$21:$A$502,0)),"") | D17: =IFERROR(INDEX(D$21:D$502,MATCH($A17,$A$21:$A$502,0)),"") | E17: =IFERROR(INDEX(E$21:E$502,MATCH($A17,$A$21:$A$502,0)),"") | F17: =IFERROR(INDEX(F$21:F$502,MATCH($A17,$A$21:$A$502,0)),"") | G17: =IFERROR(INDEX(G$21:G$502,MATCH($A17,$A$21:$A$502,0)),"") | H17: =IFERROR(INDEX(H$21:H$502,MATCH($A17,$A$21:$A$502,0)),"") | I17: =IFERROR(INDEX(I$21:I$502,MATCH($A17,$A$21:$A$502,0)),"") | ... M17: =IFERROR(INDEX(M$21:M$502,MATCH($A17,$A$21:$A$502,0)),"")
A18: =主頁!F21 -> 0 | B18: =IFERROR(INDEX(B$21:B$502,MATCH($A18,$A$21:$A$502,0)),"") | C18: =IFERROR(INDEX(C$21:C$502,MATCH($A18,$A$21:$A$502,0)),"") | D18: =IFERROR(INDEX(D$21:D$502,MATCH($A18,$A$21:$A$502,0)),"") | E18: =IFERROR(INDEX(E$21:E$502,MATCH($A18,$A$21:$A$502,0)),"") | F18: =IFERROR(INDEX(F$21:F$502,MATCH($A18,$A$21:$A$502,0)),"") | G18: =IFERROR(INDEX(G$21:G$502,MATCH($A18,$A$21:$A$502,0)),"") | H18: =IFERROR(INDEX(H$21:H$502,MATCH($A18,$A$21:$A$502,0)),"") | I18: =IFERROR(INDEX(I$21:I$502,MATCH($A18,$A$21:$A$502,0)),"") | ... M18: =IFERROR(INDEX(M$21:M$502,MATCH($A18,$A$21:$A$502,0)),"")
F20: UQ | G20: Median | H20: LQ | I20: 你的分數 | J20: 學額 | K20: 取錄人數 | L20: BandA競爭人數 | M20: 資格 | AB20: \
A21: ='Reference Score Calculation'!B13 -> JS1000 | B21: ='Reference Score Calculation'!C13 -> CityU | C21: ='Reference Score Calculation'!E13 -> 理學士(計算金融及金融科技) (專修：計算金融 / 金融科技) | D21: ='Reference Score Calculation'!S13 -> BScCFFT | E21: ='Reference Score Calculation'!F13 -> 3C2X | F21: ='Reference Score Calculation'!H13 -> / | G21: ='Reference Score Calculation'!I13 -> 24.5 | H21: ='Reference Score Calculation'!J13 -> / | I21: =計分版!J36 -> 2.3e-09 | J21: ='Reference Score Calculation'!U13 -> 10 | K21: ='Reference Score Calculation'!V13 -> 2 | L21: ='Reference Score Calculation'!Y13 -> 40.5 | M21: =入學要求!Z22 -> 0
A22: ='Reference Score Calculation'!B14 -> JS1001 | B22: ='Reference Score Calculation'!C14 -> CityU | C22: ='Reference Score Calculation'!E14 -> 工商管理學士(環球商業) (特點: 三次海外交流 / 美國哥倫比亞大學雙聯學士學位 / 海外暑期及遊學課程 / 商業諮詢課程 / 獎學金及資助) | D22: ='Reference Score Calculation'!S14 -> BBAGBU | E22: ='Reference Score Calculation'!F14 -> 3C2X | F22: ='Reference Score Calculation'!H14 -> / | G22: ='Reference Score Calculation'!I14 -> 29 | H22: ='Reference Score Calculation'!J14 -> 25.5 | I22: =計分版!J37 -> 2.3e-09 | J22: ='Reference Score Calculation'!U14 -> 15 | K22: ='Reference Score Calculation'!V14 -> 4 | L22: ='Reference Score Calculation'!Y14 -> 100 | M22: =入學要求!Z23 -> 0
A23: ='Reference Score Calculation'!B15 -> JS1002 | B23: ='Reference Score Calculation'!C15 -> CityU | C23: ='Reference Score Calculation'!E15 -> 工商管理學士(會計) (專修: 專業會計 / 環境，社會，治理和科技) | D23: ='Reference Score Calculation'!S15 -> BBAAC | E23: ='Reference Score Calculation'!F15 -> Best 5 | F23: ='Reference Score Calculation'!H15 -> / | G23: ='Reference Score Calculation'!I15 -> 20.5 | H23: ='Reference Score Calculation'!J15 -> 20 | I23: =計分版!J38 -> 3.3e-09 | J23: ='Reference Score Calculation'!U15 -> 148 | K23: ='Reference Score Calculation'!V15 -> 131 | L23: ='Reference Score Calculation'!Y15 -> 8.015748 | M23: =入學要求!Z24 -> 0
A24: ='Reference Score Calculation'!B16 -> JS1005 | B24: ='Reference Score Calculation'!C16 -> CityU | C24: ='Reference Score Calculation'!E16 -> 工商管理學士 (管理學 ) (專修 : 人 力資源管理 / 策略及國際管理 ) | D24: ='Reference Score Calculation'!S16 -> BBAMGMT | E24: ='Reference Score Calculation'!F16 -> Best 5 | F24: ='Reference Score Calculation'!H16 -> / | G24: ='Reference Score Calculation'!I16 -> 20.5 | H24: ='Reference Score Calculation'!J16 -> 20.5 | I24: =計分版!J39 -> 3.3e-09 | J24: ='Reference Score Calculation'!U16 -> 58 | K24: ='Reference Score Calculation'!V16 -> 42 | L24: ='Reference Score Calculation'!Y16 -> 19.216216 | M24: =入學要求!Z25 -> 0
A25: ='Reference Score Calculation'!B17 -> JS1007 | B25: ='Reference Score Calculation'!C17 -> CityU | C25: ='Reference Score Calculation'!E17 -> 工商管理學士(市場營銷) (專修: 環球市場營銷 / 營銷數據分析) | D25: ='Reference Score Calculation'!S17 -> BBAMKT | E25: ='Reference Score Calculation'!F17 -> 3C2X | F25: ='Reference Score Calculation'!H17 -> / | G25: ='Reference Score Calculation'!I17 -> 23.5 | H25: ='Reference Score Calculation'!J17 -> 22 | I25: =計分版!J40 -> 2.4e-09 | J25: ='Reference Score Calculation'!U17 -> 82 | K25: ='Reference Score Calculation'!V17 -> 76 | L25: ='Reference Score Calculation'!Y17 -> 12.972222 | M25: =入學要求!Z26 -> 0
A26: ='Reference Score Calculation'!B18 -> JS1012 | B26: ='Reference Score Calculation'!C18 -> CityU | C26: ='Reference Score Calculation'!E18 -> 經濟及金融 [主修: 工商管理學士(商業經濟) / 工商管理學士(金融)] | D26: ='Reference Score Calculation'!S18 -> EF | E26: ='Reference Score Calculation'!F18 -> Best 5 | F26: ='Reference Score Calculation'!H18 -> / | G26: ='Reference Score Calculation'!I18 -> 21.5 | H26: ='Reference Score Calculation'!J18 -> 21.5 | I26: =計分版!J41 -> 3.3e-09 | J26: ='Reference Score Calculation'!U18 -> 29 | K26: ='Reference Score Calculation'!V18 -> 21 | L26: ='Reference Score Calculation'!Y18 -> 11.761905 | M26: =入學要求!Z27 -> 0
A27: ='Reference Score Calculation'!B19 -> JS1013 | B27: ='Reference Score Calculation'!C19 -> CityU | C27: ='Reference Score Calculation'!E19 -> 工商管理學士(商業經濟) (特點: 經濟理論 / 國際經濟 / 經濟與商業預測 / 定量分析) | D27: ='Reference Score Calculation'!S19 -> BBABE | E27: ='Reference Score Calculation'!F19 -> Best 5 | F27: ='Reference Score Calculation'!H19 -> / | G27: ='Reference Score Calculation'!I19 -> 20.5 | H27: ='Reference Score Calculation'!J19 -> 20.5 | I27: =計分版!J42 -> 3.3e-09 | J27: ='Reference Score Calculation'!U19 -> 31 | K27: ='Reference Score Calculation'!V19 -> 32 | L27: ='Reference Score Calculation'!Y19 -> 14.875 | M27: =入學要求!Z28 -> 0
A28: ='Reference Score Calculation'!B20 -> JS1014 | B28: ='Reference Score Calculation'!C20 -> CityU | C28: ='Reference Score Calculation'!E20 -> 工商管理學士(金融) (特點: 投資分析 / 金融市場 / 公司金融/ 風險管理 / 交易室工作坊) | D28: ='Reference Score Calculation'!S20 -> BBAFIN | E28: ='Reference Score Calculation'!F20 -> Best 5 | F28: ='Reference Score Calculation'!H20 -> / | G28: ='Reference Score Calculation'!I20 -> 20.5 | H28: ='Reference Score Calculation'!J20 -> 20.5 | I28: =計分版!J43 -> 3.3e-09 | J28: ='Reference Score Calculation'!U20 -> 96 | K28: ='Reference Score Calculation'!V20 -> 102 | L28: ='Reference Score Calculation'!Y20 -> 7.4117647 | M28: =入學要求!Z29 -> 0
A29: ='Reference Score Calculation'!B21 -> JS1017 | B29: ='Reference Score Calculation'!C21 -> CityU | C29: ='Reference Score Calculation'!E21 -> 資訊系統學 [主修: 工商管理學士(環球商業系統管理) 、工商管理學士(資訊管理)] | D29: ='Reference Score Calculation'!S21 -> IS | E29: ='Reference Score Calculation'!F21 -> 3C2X | F29: ='Reference Score Calculation'!H21 -> / | G29: ='Reference Score Calculation'!I21 -> 20.5 | H29: ='Reference Score Calculation'!J21 -> 19.5 | I29: =計分版!J44 -> 2.3e-09 | J29: ='Reference Score Calculation'!U21 -> 62 | K29: ='Reference Score Calculation'!V21 -> 59 | L29: ='Reference Score Calculation'!Y21 -> 5.962963 | M29: =入學要求!Z30 -> 0
A30: ='Reference Score Calculation'!B22 -> JS1018 | B30: ='Reference Score Calculation'!C22 -> CityU | C30: ='Reference Score Calculation'!E22 -> 工商管理學士(環球商業系統管理) (特點: 智能科技 / 環球商業 / 海外及内地交流) | D30: ='Reference Score Calculation'!S22 -> BBAGBSM | E30: ='Reference Score Calculation'!F22 -> 3C2X | F30: ='Reference Score Calculation'!H22 -> / | G30: ='Reference Score Calculation'!I22 -> 22 | H30: ='Reference Score Calculation'!J22 -> 22 | I30: =計分版!J45 -> 2.3e-09 | J30: ='Reference Score Calculation'!U22 -> 10 | K30: ='Reference Score Calculation'!V22 -> 8 | L30: ='Reference Score Calculation'!Y22 -> 10.5 | M30: =入學要求!Z31 -> 0
A31: ='Reference Score Calculation'!B23 -> JS1019 | B31: ='Reference Score Calculation'!C23 -> CityU | C31: ='Reference Score Calculation'!E23 -> 工商管理學士(資訊管理) (專修: 商務智能 / 信息系統審計 / 互聯網服務及社交網絡 / 數據信息學) | D31: ='Reference Score Calculation'!S23 -> BBAIFMG | E31: ='Reference Score Calculation'!F23 -> 3C2X | F31: ='Reference Score Calculation'!H23 -> / | G31: ='Reference Score Calculation'!I23 -> 20.5 | H31: ='Reference Score Calculation'!J23 -> 19.5 | I31: =計分版!J46 -> 2.3e-09 | J31: ='Reference Score Calculation'!U23 -> 10 | K31: ='Reference Score Calculation'!V23 -> 7 | L31: ='Reference Score Calculation'!Y23 -> 22 | M31: =入學要求!Z32 -> 0
A32: ='Reference Score Calculation'!B24 -> JS1025 | B32: ='Reference Score Calculation'!C24 -> CityU | C32: ='Reference Score Calculation'!E24 -> 決策分析及營運學 [主修: 工商管理學士(商業決策分析) / 工商管理學士(環球營運管理)] | D32: ='Reference Score Calculation'!S24 -> DAO | E32: ='Reference Score Calculation'!F24 -> 3C2X | F32: ='Reference Score Calculation'!H24 -> / | G32: ='Reference Score Calculation'!I24 -> 20 | H32: ='Reference Score Calculation'!J24 -> 19.5 | I32: =計分版!J47 -> 2.3e-09 | J32: ='Reference Score Calculation'!U24 -> 24 | K32: ='Reference Score Calculation'!V24 -> 24 | L32: ='Reference Score Calculation'!Y24 -> 18.909091 | M32: =入學要求!Z33 -> 0
... A455: ='Reference Score Calculation'!B447 -> JSSY02 | B455: ='Reference Score Calculation'!C447 -> SSSDP | C455: ='Reference Score Calculation'!E447 -> 應用數據科學（榮譽）理學士 | D455: ='Reference Score Calculation'!S447 -> BSc (Hons) ADS | E455: ='Reference Score Calculation'!F447 -> 25年新科目 | F455: ='Reference Score Calculation'!H447 -> / | G455: ='Reference Score Calculation'!I447 -> 16 | H455: ='Reference Score Calculation'!J447 -> / | I455: =計分版!J470 -> 3.5e-09 | J455: ='Reference Score Calculation'!U447 -> 30 | K455: ='Reference Score Calculation'!V447 -> / | L455: ='Reference Score Calculation'!Y447 -> 新科目 | M455: =入學要求!Z456 -> 0
I637: 學額

Sheet All in One
A2: . | C2: All in One 超級計分器
D4: 請在此手動輸入科目的JUPAS編號
C7: 輸入JUPAS編號 | E7: 院校 | F7: 課程/學科 | L7: 學額 | O7: 2024年取錄人數
C8: JS5331 | E8: ='Reference Score Calculation'!C4 -> HKUST | F8: ='Reference Score Calculation'!E4 -> 理學士（經濟及金融學） | L8: ='Reference Score Calculation'!U4 -> 30 | O8: ='Reference Score Calculation'!V4 -> 33
E10: 中文 | F10: 英文 | G10: 數學 | H10: 公社科 | I10: X1 | J10: X2 | L10: 合乎基本入學要求? | O10: Band A競爭人數
C11: 基本入學要求 | E11: =入學要求!L18 -> 3 | F11: =入學要求!M18 -> 4 | G11: =入學要求!N18 -> 3 | H11: =入學要求!O18 -> 1 | I11: =入學要求!P18 -> 3 | J11: =入學要求!Q18 -> 3 | L11: =IF(入學要求!Z18=0, "否",IF(入學要求!Z18=2,"或有額外要求",IF(入學要求!Z18=1,"是"))) -> 否 | O11: ='Reference Score Calculation'!Y4 -> 3.18
E12: ='Reference Score Calculation'!AA4 -> 申請人必須出席面試 | L12: (「是」 不等如夠分入讀) | O12: (幾多人爭一個位)
E13: ='Reference Score Calculation'!AB4
C16: 上年計分方式︰ | E16: ='Reference Score Calculation'!F4 -> 英數Best3 | G16: ='Reference Score Calculation'!N4 | S16: 由於每年分數計算方式或會更改，
C17: (2024年) | G17: ='Reference Score Calculation'!O4 | S17: 此計分器一律會以*上年計分方式*計算你的分數，
S18: 以便估計與上年度收生分數的差距。
C19: 比重︰ | E19: 加分制 (5**→8.5) | G19: ='Reference Score Calculation'!P4 -> 英文x2 + 數學x2
E20: ='Reference Score Calculation'!T4 -> 有 | G20: ='Reference Score Calculation'!Q4 -> + 最佳三科x1 或
G21: ='Reference Score Calculation'!R4 -> + [化學、經濟、物理、M1/2]中最佳一科x1.5 + 最佳兩科x1
C25: 今年計分方式︰ | E25: ='Reference Score Calculation'!AC4 -> 英數Best3 | G25: ='Reference Score Calculation'!AF4 | S25: 此處將列出今年度計分方式 及 比重詳情，
C26: (2025年) | G26: ='Reference Score Calculation'!AG4 | S26: 以供大家參考 及 估算自己入讀機會，敬請留意。
C28: 比重︰ | E28: 加分制 (5**→8.5) | G28: ='Reference Score Calculation'!AH4 -> 英文x2 + 數學x2
E29: ='Reference Score Calculation'!Z4 -> 有 | G29: ='Reference Score Calculation'!AI4 -> + 最佳三科x1 或
G30: ='Reference Score Calculation'!AJ4 -> + [化學、經濟、物理、M1/2]中最佳一科x1.5 + 最佳兩科x1
E32: 2025年更新事項： | G32: ='Reference Score Calculation'!AD4
G33: ='Reference Score Calculation'!AE4
C36: 其他考慮因素 | E36: ='Reference Score Calculation'!AK4 -> LQ 每科平均成績: | I36: 重考扣分 | J36: ='Reference Score Calculation'!AV4 -> 無 | L36: 面試 | M36: ='Reference Score Calculation'!AW4
E37: ='Reference Score Calculation'!AL4 -> 6.18 (已計算加分制) | M37: ='Reference Score Calculation'!AX4
E38: ='Reference Score Calculation'!AM4
C40: 額外資料 | E40: ='Reference Score Calculation'!AN4 -> 申請人必須出席面試
E41: ='Reference Score Calculation'!AO4
E42: ='Reference Score Calculation'!AP4
E43: ='Reference Score Calculation'!AQ4 -> 此課程的加權後的 *最高可考獲分數* 為: 66.94
E44: ='Reference Score Calculation'!AR4 -> 科大會根據同學的第六科成績獎勵最高5%的額外分數，計算方式如下︰
E45: ='Reference Score Calculation'!AS4 -> 8.5分 -> 5% | 7分 -> 4.12% | 5.5分 -> 3.24% | 4分 -> 2.35% | 3分 -> 1.76%
F49: =計分版!AP24 -> 0 | G49: =計分版!AQ24 -> 1 | H49: =計分版!AR24 -> 1 | I49: =計分版!AS24 -> 0 | J49: =計分版!AT24 -> 0 | K49: =計分版!AU24 -> 0 | L49: =計分版!AV24 -> 1 | M49: =計分版!AW24 -> 1 | ... O49: =計分版!AY24 -> 0 | S49: For HKU & HKUST Only
F51: 中文 | G51: 英文 | H51: 數學 | J51: M1/2 | K51: =IF(計分版!P$1="請選擇第一選修科","無",計分版!P$1) -> 無 | L51: =IF(計分版!Q$1="請選擇第二選修科","無",計分版!Q$1) -> 無 | M51: =IF(計分版!R$1="請選擇第三選修科","無",計分版!R$1) -> 無 | N51: =IF(計分版!S$1="請選擇第四選修科","無",計分版!S$1) -> 無 | O51: =IF(計分版!T$1="請選擇語言科目","無",計分版!T$1) -> 無 | S51: 第6/7科最佳 | U51: Bonus 分數
C52: 你的分數 | D52: =計分版!J24 -> 0 | F52: =IFERROR(計分版!K31,"") -> 0 | G52: =IFERROR(計分版!L31,"") -> 0 | H52: =IFERROR(計分版!M31,"") -> 0 | J52: =IFERROR(計分版!O31,"") -> 0 | K52: =IFERROR(計分版!P31,"") -> 0 | L52: =IFERROR(計分版!Q31,"") -> 0 | M52: =IFERROR(計分版!R31,"") -> 0 | N52: =IFERROR(計分版!S31,"") -> 0 | O52: =IFERROR(計分版!T31,"") -> 0 | S52: =計分版!BC23 -> 請選擇第一選修科 | U52: =計分版!BE23 -> 1
E53: 比重 | F53: =計分版!K24 -> 1 | G53: =計分版!L24 -> 2 | H53: =計分版!M24 -> 2 | J53: =計分版!O24 -> 1 | K53: =計分版!P24 -> 1 | L53: =計分版!Q24 -> 1 | M53: =計分版!R24 -> 1 | N53: =計分版!S24 -> 1 | O53: =計分版!T24 -> 1
C54: 計分方式︰ | D54: ='Reference Score Calculation'!F4 -> 英數Best3 | F54: =IF(計分版!V24<1,0,計分版!V24) -> 0 | G54: =IF(計分版!W24<1,0,計分版!W24) -> 0 | H54: =IF(計分版!X24<1,0,計分版!X24) -> 0 | J54: =IF(計分版!Z24<1,0,計分版!Z24) -> 0 | K54: =IF(計分版!AA24<1,0,計分版!AA24) -> 0 | L54: =IF(計分版!AB24<1,0,計分版!AB24) -> 0 | M54: =IF(計分版!AC24<1,0,計分版!AC24) -> 0 | N54: =IF(計分版!AD24<1,0,計分版!AD24) -> 0 | O54: =IF(計分版!AE24<1,0,計分版!AE24) -> 0 | S54: =計分版!BF23 -> Best 5總分 x 1
F58: 中文 | G58: 英文 | H58: 數學 | J58: M1/2 | K58: X1 | L58: X2 | M58: X3
C59: LQ | D59: ='Reference Score Calculation'!J4 -> 48.56 | F59: ='Reference Score Calculation'!BI4 | G59: ='Reference Score Calculation'!BJ4 | H59: ='Reference Score Calculation'!BK4 | J59: ='Reference Score Calculation'!BM4 | K59: ='Reference Score Calculation'!BN4 | L59: ='Reference Score Calculation'!BO4 | M59: ='Reference Score Calculation'!BP4 | O59: ='Reference Score Calculation'!AT4 -> 此參考分數為院校公佈的 已計比重分數，沒有估算成份。
E60: 比重 | F60: ='Reference Score Calculation'!AZ4 | G60: ='Reference Score Calculation'!BA4 | H60: ='Reference Score Calculation'!BB4 | J60: ='Reference Score Calculation'!BD4 | K60: ='Reference Score Calculation'!BE4 | L60: ='Reference Score Calculation'!BF4 | M60: ='Reference Score Calculation'!BG4 | O60: ='Reference Score Calculation'!AU4
C61: 相差 | D61: =IFERROR(($D$52-D59)/D59,0) -> -1 | F61: ='Reference Score Calculation'!BY4 | G61: ='Reference Score Calculation'!BZ4 | H61: ='Reference Score Calculation'!CA4 | J61: ='Reference Score Calculation'!CC4 | K61: ='Reference Score Calculation'!CD4 | L61: ='Reference Score Calculation'!CE4 | M61: ='Reference Score Calculation'!CF4
F62: ='Reference Score Calculation'!CG4 | G62: ='Reference Score Calculation'!CH4 | H62: ='Reference Score Calculation'!CI4 | J62: ='Reference Score Calculation'!CK4 | K62: ='Reference Score Calculation'!CL4 | L62: ='Reference Score Calculation'!CM4 | M62: ='Reference Score Calculation'!CN4
...

Sheet CityU
A1: 編號 | B1: 學院 | C1: 課程/學科 | E1: 25年新計分方式 | F1: 24年計分方式 | G1: Median | H1: LQ | I1: 你的分數 | J1: 差距(Median) | L1: 學額 | M1: 資格 | O1: 中 | P1: 英 | Q1: 數 | R1: 公 | S1: E1 | T1: E2 | AA1: Band A 競爭 | AB1: 取錄人數 | AC1: Total | AD1: Band A | AE1: Band B | AF1: Band C | AG1: Band D | AH1: Band E | AI1: 申請人數 | AJ1: Total | AK1: Band A | AL1: Band B | AM1: Band C | AN1: Band D | AO1: Band E
A2: ='Reference Score Calculation'!B13 -> JS1000 | B2: ='Reference Score Calculation'!D13 -> 商學院 | C2: ='Reference Score Calculation'!E13 -> 理學士(計算金融及金融科技) (專修：計算金融 / 金融科技) | D2: ='Reference Score Calculation'!S13 -> BScCFFT | E2: ='Reference Score Calculation'!AC13 -> 3C2X | F2: ='Reference Score Calculation'!F13 -> 3C2X | G2: ='Reference Score Calculation'!I13 -> 24.5 | H2: ='Reference Score Calculation'!J13 -> / | I2: =計分版!J36 -> 2.3e-09 | J2: =IFERROR(IF(J$1="差距(Median)",I2-G2,IF(J$1="差距(LQ)",I2-H2)),"/") -> -24.5 | K2: =IFERROR(IF(J$1="差距(Median)",(I2-G2)/I2,IF(J$1="差距(LQ)",(I2-H2)/I2)),"/") -> -1.0652174e+10 | L2: ='Reference Score Calculation'!U13 -> 10 | M2: =入學要求!Z22 -> 0 | N2: 請前往All in One 計分器查看比重、入學要求等詳情。 | O2: =入學要求!L22 -> 3 | P2: =入學要求!M22 -> 3 | Q2: =入學要求!N22 -> 4 | R2: =入學要求!O22 -> 1 | S2: =入學要求!P22 -> 3 | T2: =入學要求!Q22 -> 3 | U2: =入學要求!S22 -> 0 | V2: =入學要求!T22 -> 0 | W2: =入學要求!U22 -> 0 | X2: =入學要求!V22 -> 0 | Y2: =入學要求!W22 -> 0 | Z2: =入學要求!X22 -> 0 | AA2: =IFERROR(ROUND(AK2/AD2,2),"/") -> 40.5 | AB2: 2024年 | AC2: {=IFERROR(INDEX('Offer Statistics'!$Q$2:$Q$500,MATCH(1,(CityU!$A2='Offer Statistics'!$B$2:$B$500)*(CityU!$AB$2='Offer Statistics'!$K$2:$K$500),0)),"/")} -> 2 | AD2: {=IFERROR(INDEX('Offer Statistics'!L$2:L$500,MATCH(1,(CityU!$A2='Offer Statistics'!$B$2:$B$500)*(CityU!$AB$2='Offer Statistics'!$K$2:$K$500),0)),"/")} -> 2 | AE2: {=IFERROR(INDEX('Offer Statistics'!M$2:M$500,MATCH(1,(CityU!$A2='Offer Statistics'!$B$2:$B$500)*(CityU!$AB$2='Offer Statistics'!$K$2:$K$500),0)),"/")} -> 0 | AF2: {=IFERROR(INDEX('Offer Statistics'!N$2:N$500,MATCH(1,(CityU!$A2='Offer Statistics'!$B$2:$B$500)*(CityU!$AB$2='Offer Statistics'!$K$2:$K$500),0)),"/")} -> 0 | AG2: {=IFERROR(INDEX('Offer Statistics'!O$2:O$500,MATCH(1,(CityU!$A2='Offer Statistics'!$B$2:$B$500)*(CityU!$AB$2='Offer Statistics'!$K$2:$K$500),0)),"/")} -> 0 | AH2: {=IFERROR(INDEX('Offer Statistics'!P$2:P$500,MATCH(1,(CityU!$A2='Offer Statistics'!$B$2:$B$500)*(CityU!$AB$2='Offer Statistics'!$K$2:$K$500),0)),"/")} -> 0 | AI2: =AB2 -> 2024年 | AJ2: {=IFERROR(INDEX('Offer Statistics'!$I$2:$I$500,MATCH(1,(CityU!$A2='Offer Statistics'!$B$2:$B$500)*(CityU!$AB$2='Offer Statistics'!$C$2:$C$500),0)),"/")} -> 1254 | AK2: {=IFERROR(INDEX('Offer Statistics'!D$2:D$500,MATCH(1,(CityU!$A2='Offer Statistics'!$B$2:$B$500)*(CityU!$AB$2='Offer Statistics'!$C$2:$C$500),0)),"/")} -> 81 | AL2: {=IFERROR(INDEX('Offer Statistics'!E$2:E$500,MATCH(1,(CityU!$A2='Offer Statistics'!$B$2:$B$500)*(CityU!$AB$2='Offer Statistics'!$C$2:$C$500),0)),"/")} -> 151 | AM2: {=IFERROR(INDEX('Offer Statistics'!F$2:F$500,MATCH(1,(CityU!$A2='Offer Statistics'!$B$2:$B$500)*(CityU!$AB$2='Offer Statistics'!$C$2:$C$500),0)),"/")} -> 309 | AN2: {=IFERROR(INDEX('Offer Statistics'!G$2:G$500,MATCH(1,(CityU!$A2='Offer Statistics'!$B$2:$B$500)*(CityU!$AB$2='Offer Statistics'!$C$2:$C$500),0)),"/")} -> 390 | AO2: {=IFERROR(INDEX('Offer Statistics'!H$2:H$500,MATCH(1,(CityU!$A2='Offer Statistics'!$B$2:$B$500)*(CityU!$AB$2='Offer Statistics'!$C$2:$C$500),0)),"/")} -> 323 | AQ2: =A2 -> JS1000
A3: ='Reference Score Calculation'!B14 -> JS1001 | B3: ='Reference Score Calculation'!D14 -> 商學院 | C3: ='Reference Score Calculation'!E14 -> 工商管理學士(環球商業) (特點: 三次海外交流 / 美國哥倫比亞大學雙聯學士學位 / 海外暑期及遊學課程 / 商業諮詢課程 / 獎學金及資助) | D3: ='Reference Score Calculation'!S14 -> BBAGBU | E3: ='Reference Score Calculation'!AC14 -> 3C2X | F3: ='Reference Score Calculation'!F14 -> 3C2X | G3: ='Reference Score Calculation'!I14 -> 29 | H3: ='Reference Score Calculation'!J14 -> 25.5 | I3: =計分版!J37 -> 2.3e-09 | J3: =IFERROR(IF(J$1="差距(Median)",I3-G3,IF(J$1="差距(LQ)",I3-H3)),"/") -> -29 | K3: =IFERROR(IF(J$1="差距(Median)",(I3-G3)/I3,IF(J$1="差距(LQ)",(I3-H3)/I3)),"/") -> -1.2608696e+10 | L3: ='Reference Score Calculation'!U14 -> 15 | M3: =入學要求!Z23 -> 0 | O3: =入學要求!L23 -> 3 | P3: =入學要求!M23 -> 3 | Q3: =入學要求!N23 -> 3 | R3: =入學要求!O23 -> 1 | S3: =入學要求!P23 -> 3 | T3: =入學要求!Q23 -> 3 | U3: =入學要求!S23 -> 0 | V3: =入學要求!T23 -> 0 | W3: =入學要求!U23 -> 0 | X3: =入學要求!V23 -> 0 | Y3: =入學要求!W23 -> 0 | Z3: =入學要求!X23 -> 0 | AA3: =IFERROR(ROUND(AK3/AD3,2),"/") -> 100 | AC3: {=IFERROR(INDEX('Offer Statistics'!$Q$2:$Q$500,MATCH(1,(CityU!$A3='Offer Statistics'!$B$2:$B$500)*(CityU!$AB$2='Offer Statistics'!$K$2:$K$500),0)),"/")} -> 4 | AD3: {=IFERROR(INDEX('Offer Statistics'!L$2:L$500,MATCH(1,(CityU!$A3='Offer Statistics'!$B$2:$B$500)*(CityU!$AB$2='Offer Statistics'!$K$2:$K$500),0)),"/")} -> 1 | AE3: {=IFERROR(INDEX('Offer Statistics'!M$2:M$500,MATCH(1,(CityU!$A3='Offer Statistics'!$B$2:$B$500)*(CityU!$AB$2='Offer Statistics'!$K$2:$K$500),0)),"/")} -> 3 | AF3: {=IFERROR(INDEX('Offer Statistics'!N$2:N$500,MATCH(1,(CityU!$A3='Offer Statistics'!$B$2:$B$500)*(CityU!$AB$2='Offer Statistics'!$K$2:$K$500),0)),"/")} -> 0 | AG3: {=IFERROR(INDEX('Offer Statistics'!O$2:O$500,MATCH(1,(CityU!$A3='Offer Statistics'!$B$2:$B$500)*(CityU!$AB$2='Offer Statistics'!$K$2:$K$500),0)),"/")} -> 0 | AH3: {=IFERROR(INDEX('Offer Statistics'!P$2:P$500,MATCH(1,(CityU!$A3='Offer Statistics'!$B$2:$B$500)*(CityU!$AB$2='Offer Statistics'!$K$2:$K$500),0)),"/")} -> 0 | AJ3: {=IFERROR(INDEX('Offer Statistics'!$I$2:$I$500,MATCH(1,(CityU!$A3='Offer Statistics'!$B$2:$B$500)*(CityU!$AB$2='Offer Statistics'!$C$2:$C$500),0)),"/")} -> 1849 | AK3: {=IFERROR(INDEX('Offer Statistics'!D$2:D$500,MATCH(1,(CityU!$A3='Offer Statistics'!$B$2:$B$500)*(CityU!$AB$2='Offer Statistics'!$C$2:$C$500),0)),"/")} -> 100 | AL3: {=IFERROR(INDEX('Offer Statistics'!E$2:E$500,MATCH(1,(CityU!$A3='Offer Statistics'!$B$2:$B$500)*(CityU!$AB$2='Offer Statistics'!$C$2:$C$500),0)),"/")} -> 292 | AM3: {=IFERROR(INDEX('Offer Statistics'!F$2:F$500,MATCH(1,(CityU!$A3='Offer Statistics'!$B$2:$B$500)*(CityU!$AB$2='Offer Statistics'!$C$2:$C$500),0)),"/")} -> 443 | AN3: {=IFERROR(INDEX('Offer Statistics'!G$2:G$500,MATCH(1,(CityU!$A3='Offer Statistics'!$B$2:$B$500)*(CityU!$AB$2='Offer Statistics'!$C$2:$C$500),0)),"/")} -> 564 | AO3: {=IFERROR(INDEX('Offer Statistics'!H$2:H$500,MATCH(1,(CityU!$A3='Offer Statistics'!$B$2:$B$500)*(CityU!$AB$2='Offer Statistics'!$C$2:$C$500),0)),"/")} -> 450 | AQ3: =A3 -> JS1001
A4: ='Reference Score Calculation'!B15 -> JS1002 | B4: ='Reference Score Calculation'!D15 -> 商學院 | C4: ='Reference Score Calculation'!E15 -> 工商管理學士(會計) (專修: 專業會計 / 環境，社會，治理和科技) | D4: ='Reference Score Calculation'!S15 -> BBAAC | E4: ='Reference Score Calculation'!AC15 -> Best 5 | F4: ='Reference Score Calculation'!F15 -> Best 5 | G4: ='Reference Score Calculation'!I15 -> 20.5 | H4: ='Reference Score Calculation'!J15 -> 20 | I4: =計分版!J38 -> 3.3e-09 | J4: =IFERROR(IF(J$1="差距(Median)",I4-G4,IF(J$1="差距(LQ)",I4-H4)),"/") -> -20.5 | K4: =IFERROR(IF(J$1="差距(Median)",(I4-G4)/I4,IF(J$1="差距(LQ)",(I4-H4)/I4)),"/") -> -6.2121212e+09 | L4: ='Reference Score Calculation'!U15 -> 148 | M4: =入學要求!Z24 -> 0 | O4: =入學要求!L24 -> 3 | P4: =入學要求!M24 -> 3 | Q4: =入學要求!N24 -> 3 | R4: =入學要求!O24 -> 1 | S4: =入學要求!P24 -> 3 | T4: =入學要求!Q24 -> 3 | U4: =入學要求!S24 -> 0 | V4: =入學要求!T24 -> 0 | W4: =入學要求!U24 -> 0 | X4: =入學要求!V24 -> 0 | Y4: =入學要求!W24 -> 0 | Z4: =入學要求!X24 -> 0 | AA4: =IFERROR(ROUND(AK4/AD4,2),"/") -> 8.02 | AC4: {=IFERROR(INDEX('Offer Statistics'!$Q$2:$Q$500,MATCH(1,(CityU!$A4='Offer Statistics'!$B$2:$B$500)*(CityU!$AB$2='Offer Statistics'!$K$2:$K$500),0)),"/")} -> 131 | AD4: {=IFERROR(INDEX('Offer Statistics'!L$2:L$500,MATCH(1,(CityU!$A4='Offer Statistics'!$B$2:$B$500)*(CityU!$AB$2='Offer Statistics'!$K$2:$K$500),0)),"/")} -> 127 | AE4: {=IFERROR(INDEX('Offer Statistics'!M$2:M$500,MATCH(1,(CityU!$A4='Offer Statistics'!$B$2:$B$500)*(CityU!$AB$2='Offer Statistics'!$K$2:$K$500),0)),"/")} -> 2 | AF4: {=IFERROR(INDEX('Offer Statistics'!N$2:N$500,MATCH(1,(CityU!$A4='Offer Statistics'!$B$2:$B$500)*(CityU!$AB$2='Offer Statistics'!$K$2:$K$500),0)),"/")} -> 1 | AG4: {=IFERROR(INDEX('Offer Statistics'!O$2:O$500,MATCH(1,(CityU!$A4='Offer Statistics'!$B$2:$B$500)*(CityU!$AB$2='Offer Statistics'!$K$2:$K$500),0)),"/")} -> 1 | AH4: {=IFERROR(INDEX('Offer Statistics'!P$2:P$500,MATCH(1,(CityU!$A4='Offer Statistics'!$B$2:$B$500)*(CityU!$AB$2='Offer Statistics'!$K$2:$K$500),0)),"/")} -> 0 | AJ4: {=IFERROR(INDEX('Offer Statistics'!$I$2:$I$500,MATCH(1,(CityU!$A4='Offer Statistics'!$B$2:$B$500)*(CityU!$AB$2='Offer Statistics'!$C$2:$C$500),0)),"/")} -> 4045 | AK4: {=IFERROR(INDEX('Offer Statistics'!D$2:D$500,MATCH(1,(CityU!$A4='Offer Statistics'!$B$2:$B$500)*(CityU!$AB$2='Offer Statistics'!$C$2:$C$500),0)),"/")} -> 1018 | AL4: {=IFERROR(INDEX('Offer Statistics'!E$2:E$500,MATCH(1,(CityU!$A4='Offer Statistics'!$B$2:$B$500)*(CityU!$AB$2='Offer Statistics'!$C$2:$C$500),0)),"/")} -> 758 | AM4: {=IFERROR(INDEX('Offer Statistics'!F$2:F$500,MATCH(1,(CityU!$A4='Offer Statistics'!$B$2:$B$500)*(CityU!$AB$2='Offer Statistics'!$C$2:$C$500),0)),"/")} -> 904 | AN4: {=IFERROR(INDEX('Offer Statistics'!G$2:G$500,MATCH(1,(CityU!$A4='Offer Statistics'!$B$2:$B$500)*(CityU!$AB$2='Offer Statistics'!$C$2:$C$500),0)),"/")} -> 852 | AO4: {=IFERROR(INDEX('Offer Statistics'!H$2:H$500,MATCH(1,(CityU!$A4='Offer Statistics'!$B$2:$B$500)*(CityU!$AB$2='Offer Statistics'!$C$2:$C$500),0)),"/")} -> 513 | AQ4: =A4 -> JS1002
A5: ='Reference Score Calculation'!B16 -> JS1005 | B5: ='Reference Score Calculation'!D16 -> 商學院 | C5: ='Reference Score Calculation'!E16 -> 工商管理學士 (管理學 ) (專修 : 人 力資源管理 / 策略及國際管理 ) | D5: ='Reference Score Calculation'!S16 -> BBAMGMT | E5: ='Reference Score Calculation'!AC16 -> Best 5 | F5: ='Reference Score Calculation'!F16 -> Best 5 | G5: ='Reference Score Calculation'!I16 -> 20.5 | H5: ='Reference Score Calculation'!J16 -> 20.5 | I5: =計分版!J39 -> 3.3e-09 | J5: =IFERROR(IF(J$1="差距(Median)",I5-G5,IF(J$1="差距(LQ)",I5-H5)),"/") -> -20.5 | K5: =IFERROR(IF(J$1="差距(Median)",(I5-G5)/I5,IF(J$1="差距(LQ)",(I5-H5)/I5)),"/") -> -6.2121212e+09 | L5: ='Reference Score Calculation'!U16 -> 58 | M5: =入學要求!Z25 -> 0 | O5: =入學要求!L25 -> 3 | P5: =入學要求!M25 -> 3 | Q5: =入學要求!N25 -> 3 | R5: =入學要求!O25 -> 1 | S5: =入學要求!P25 -> 3 | T5: =入學要求!Q25 -> 3 | U5: =入學要求!S25 -> 0 | V5: =入學要求!T25 -> 0 | W5: =入學要求!U25 -> 0 | X5: =入學要求!V25 -> 0 | Y5: =入學要求!W25 -> 0 | Z5: =入學要求!X25 -> 0 | AA5: =IFERROR(ROUND(AK5/AD5,2),"/") -> 19.22 | AC5: {=IFERROR(INDEX('Offer Statistics'!$Q$2:$Q$500,MATCH(1,(CityU!$A5='Offer Statistics'!$B$2:$B$500)*(CityU!$AB$2='Offer Statistics'!$K$2:$K$500),0)),"/")} -> 42 | AD5: {=IFERROR(INDEX('Offer Statistics'!L$2:L$500,MATCH(1,(CityU!$A5='Offer Statistics'!$B$2:$B$500)*(CityU!$AB$2='Offer Statistics'!$K$2:$K$500),0)),"/")} -> 37 | AE5: {=IFERROR(INDEX('Offer Statistics'!M$2:M$500,MATCH(1,(CityU!$A5='Offer Statistics'!$B$2:$B$500)*(CityU!$AB$2='Offer Statistics'!$K$2:$K$500),0)),"/")} -> 5 | AF5: {=IFERROR(INDEX('Offer Statistics'!N$2:N$500,MATCH(1,(CityU!$A5='Offer Statistics'!$B$2:$B$500)*(CityU!$AB$2='Offer Statistics'!$K$2:$K$500),0)),"/")} -> 0 | AG5: {=IFERROR(INDEX('Offer Statistics'!O$2:O$500,MATCH(1,(CityU!$A5='Offer Statistics'!$B$2:$B$500)*(CityU!$AB$2='Offer Statistics'!$K$2:$K$500),0)),"/")} -> 0 | AH5: {=IFERROR(INDEX('Offer Statistics'!P$2:P$500,MATCH(1,(CityU!$A5='Offer Statistics'!$B$2:$B$500)*(CityU!$AB$2='Offer Statistics'!$K$2:$K$500),0)),"/")} -> 0 | AJ5: {=IFERROR(INDEX('Offer Statistics'!$I$2:$I$500,MATCH(1,(CityU!$A5='Offer Statistics'!$B$2:$B$500)*(CityU!$AB$2='Offer Statistics'!$C$2:$C$500),0)),"/")} -> 5157 | AK5: {=IFERROR(INDEX('Offer Statistics'!D$2:D$500,MATCH(1,(CityU!$A5='Offer Statistics'!$B$2:$B$500)*(CityU!$AB$2='Offer Statistics'!$C$2:$C$500),0)),"/")} -> 711 | AL5: {=IFERROR(INDEX('Offer Statistics'!E$2:E$500,MATCH(1,(CityU!$A5='Offer Statistics'!$B$2:$B$500)*(CityU!$AB$2='Offer Statistics'!$C$2:$C$500),0)),"/")} -> 934 | AM5: {=IFERROR(INDEX('Offer Statistics'!F$2:F$500,MATCH(1,(CityU!$A5='Offer Statistics'!$B$2:$B$500)*(CityU!$AB$2='Offer Statistics'!$C$2:$C$500),0)),"/")} -> 1352 | AN5: {=IFERROR(INDEX('Offer Statistics'!G$2:G$500,MATCH(1,(CityU!$A5='Offer Statistics'!$B$2:$B$500)*(CityU!$AB$2='Offer Statistics'!$C$2:$C$500),0)),"/")} -> 1343 | AO5: {=IFERROR(INDEX('Offer Statistics'!H$2:H$500,MATCH(1,(CityU!$A5='Offer Statistics'!$B$2:$B$500)*(CityU!$AB$2='Offer Statistics'!$C$2:$C$500),0)),"/")} -> 817 | AQ5: =A5 -> JS1005
A6: ='Reference Score Calculation'!B17 -> JS1007 | B6: ='Reference Score Calculation'!D17 -> 商學院 | C6: ='Reference Score Calculation'!E17 -> 工商管理學士(市場營銷) (專修: 環球市場營銷 / 營銷數據分析) | D6: ='Reference Score Calculation'!S17 -> BBAMKT | E6: ='Reference Score Calculation'!AC17 -> 3C2X | F6: ='Reference Score Calculation'!F17 -> 3C2X | G6: ='Reference Score Calculation'!I17 -> 23.5 | H6: ='Reference Score Calculation'!J17 -> 22 | I6: =計分版!J40 -> 2.4e-09 | J6: =IFERROR(IF(J$1="差距(Median)",I6-G6,IF(J$1="差距(LQ)",I6-H6)),"/") -> -23.5 | K6: =IFERROR(IF(J$1="差距(Median)",(I6-G6)/I6,IF(J$1="差距(LQ)",(I6-H6)/I6)),"/") -> -9.7916667e+09 | L6: ='Reference Score Calculation'!U17 -> 82 | M6: =入學要求!Z26 -> 0 | O6: =入學要求!L26 -> 3 | P6: =入學要求!M26 -> 3 | Q6: =入學要求!N26 -> 3 | R6: =入學要求!O26 -> 1 | S6: =入學要求!P26 -> 3 | T6: =入學要求!Q26 -> 3 | U6: =入學要求!S26 -> 0 | V6: =入學要求!T26 -> 0 | W6: =入學要求!U26 -> 0 | X6: =入學要求!V26 -> 0 | Y6: =入學要求!W26 -> 0 | Z6: =入學要求!X26 -> 0 | AA6: =IFERROR(ROUND(AK6/AD6,2),"/") -> 12.97 | AC6: {=IFERROR(INDEX('Offer Statistics'!$Q$2:$Q$500,MATCH(1,(CityU!$A6='Offer Statistics'!$B$2:$B$500)*(CityU!$AB$2='Offer Statistics'!$K$2:$K$500),0)),"/")} -> 76 | AD6: {=IFERROR(INDEX('Offer Statistics'!L$2:L$500,MATCH(1,(CityU!$A6='Offer Statistics'!$B$2:$B$500)*(CityU!$AB$2='Offer Statistics'!$K$2:$K$500),0)),"/")} -> 72 | AE6: {=IFERROR(INDEX('Offer Statistics'!M$2:M$500,MATCH(1,(CityU!$A6='Offer Statistics'!$B$2:$B$500)*(CityU!$AB$2='Offer Statistics'!$K$2:$K$500),0)),"/")} -> 3 | AF6: {=IFERROR(INDEX('Offer Statistics'!N$2:N$500,MATCH(1,(CityU!$A6='Offer Statistics'!$B$2:$B$500)*(CityU!$AB$2='Offer Statistics'!$K$2:$K$500),0)),"/")} -> 0 | AG6: {=IFERROR(INDEX('Offer Statistics'!O$2:O$500,MATCH(1,(CityU!$A6='Offer Statistics'!$B$2:$B$500)*(CityU!$AB$2='Offer Statistics'!$K$2:$K$500),0)),"/")} -> 0 | AH6: {=IFERROR(INDEX('Offer Statistics'!P$2:P$500,MATCH(1,(CityU!$A6='Offer Statistics'!$B$2:$B$500)*(CityU!$AB$2='Offer Statistics'!$K$2:$K$500),0)),"/")} -> 1 | AJ6: {=IFERROR(INDEX('Offer Statistics'!$I$2:$I$500,MATCH(1,(CityU!$A6='Offer Statistics'!$B$2:$B$500)*(CityU!$AB$2='Offer Statistics'!$C$2:$C$500),0)),"/")} -> 5069 | AK6: {=IFERROR(INDEX('Offer Statistics'!D$2:D$500,MATCH(1,(CityU!$A6='Offer Statistics'!$B$2:$B$500)*(CityU!$AB$2='Offer Statistics'!$C$2:$C$500),0)),"/")} -> 934 | AL6: {=IFERROR(INDEX('Offer Statistics'!E$2:E$500,MATCH(1,(CityU!$A6='Offer Statistics'!$B$2:$B$500)*(CityU!$AB$2='Offer Statistics'!$C$2:$C$500),0)),"/")} -> 973 | AM6: {=IFERROR(INDEX('Offer Statistics'!F$2:F$500,MATCH(1,(CityU!$A6='Offer Statistics'!$B$2:$B$500)*(CityU!$AB$2='Offer Statistics'!$C$2:$C$500),0)),"/")} -> 1184 | AN6: {=IFERROR(INDEX('Offer Statistics'!G$2:G$500,MATCH(1,(CityU!$A6='Offer Statistics'!$B$2:$B$500)*(CityU!$AB$2='Offer Statistics'!$C$2:$C$500),0)),"/")} -> 1160 | AO6: {=IFERROR(INDEX('Offer Statistics'!H$2:H$500,MATCH(1,(CityU!$A6='Offer Statistics'!$B$2:$B$500)*(CityU!$AB$2='Offer Statistics'!$C$2:$C$500),0)),"/")} -> 818 | AQ6: =A6 -> JS1007
A7: ='Reference Score Calculation'!B18 -> JS1012 | B7: ='Reference Score Calculation'!D18 -> 商學院 | C7: ='Reference Score Calculation'!E18 -> 經濟及金融 [主修: 工商管理學士(商業經濟) / 工商管理學士(金融)] | D7: ='Reference Score Calculation'!S18 -> EF | E7: ='Reference Score Calculation'!AC18 -> Best 5 | F7: ='Reference Score Calculation'!F18 -> Best 5 | G7: ='Reference Score Calculation'!I18 -> 21.5 | H7: ='Reference Score Calculation'!J18 -> 21.5 | I7: =計分版!J41 -> 3.3e-09 | J7: =IFERROR(IF(J$1="差距(Median)",I7-G7,IF(J$1="差距(LQ)",I7-H7)),"/") -> -21.5 | K7: =IFERROR(IF(J$1="差距(Median)",(I7-G7)/I7,IF(J$1="差距(LQ)",(I7-H7)/I7)),"/") -> -6.5151515e+09 | L7: ='Reference Score Calculation'!U18 -> 29 | M7: =入學要求!Z27 -> 0 | O7: =入學要求!L27 -> 3 | P7: =入學要求!M27 -> 3 | Q7: =入學要求!N27 -> 3 | R7: =入學要求!O27 -> 1 | S7: =入學要求!P27 -> 3 | T7: =入學要求!Q27 -> 3 | U7: =入學要求!S27 -> 0 | V7: =入學要求!T27 -> 0 | W7: =入學要求!U27 -> 0 | X7: =入學要求!V27 -> 0 | Y7: =入學要求!W27 -> 0 | Z7: =入學要求!X27 -> 0 | AA7: =IFERROR(ROUND(AK7/AD7,2),"/") -> 11.76 | AC7: {=IFERROR(INDEX('Offer Statistics'!$Q$2:$Q$500,MATCH(1,(CityU!$A7='Offer Statistics'!$B$2:$B$500)*(CityU!$AB$2='Offer Statistics'!$K$2:$K$500),0)),"/")} -> 21 | AD7: {=IFERROR(INDEX('Offer Statistics'!L$2:L$500,MATCH(1,(CityU!$A7='Offer Statistics'!$B$2:$B$500)*(CityU!$AB$2='Offer Statistics'!$K$2:$K$500),0)),"/")} -> 21 | AE7: {=IFERROR(INDEX('Offer Statistics'!M$2:M$500,MATCH(1,(CityU!$A7='Offer Statistics'!$B$2:$B$500)*(CityU!$AB$2='Offer Statistics'!$K$2:$K$500),0)),"/")} -> 0 | AF7: {=IFERROR(INDEX('Offer Statistics'!N$2:N$500,MATCH(1,(CityU!$A7='Offer Statistics'!$B$2:$B$500)*(CityU!$AB$2='Offer Statistics'!$K$2:$K$500),0)),"/")} -> 0 | AG7: {=IFERROR(INDEX('Offer Statistics'!O$2:O$500,MATCH(1,(CityU!$A7='Offer Statistics'!$B$2:$B$500)*(CityU!$AB$2='Offer Statistics'!$K$2:$K$500),0)),"/")} -> 0 | AH7: {=IFERROR(INDEX('Offer Statistics'!P$2:P$500,MATCH(1,(CityU!$A7='Offer Statistics'!$B$2:$B$500)*(CityU!$AB$2='Offer Statistics'!$K$2:$K$500),0)),"/")} -> 0 | AJ7: {=IFERROR(INDEX('Offer Statistics'!$I$2:$I$500,MATCH(1,(CityU!$A7='Offer Statistics'!$B$2:$B$500)*(CityU!$AB$2='Offer Statistics'!$C$2:$C$500),0)),"/")} -> 2986 | AK7: {=IFERROR(INDEX('Offer Statistics'!D$2:D$500,MATCH(1,(CityU!$A7='Offer Statistics'!$B$2:$B$500)*(CityU!$AB$2='Offer Statistics'!$C$2:$C$500),0)),"/")} -> 247 | AL7: {=IFERROR(INDEX('Offer Statistics'!E$2:E$500,MATCH(1,(CityU!$A7='Offer Statistics'!$B$2:$B$500)*(CityU!$AB$2='Offer Statistics'!$C$2:$C$500),0)),"/")} -> 488 | AM7: {=IFERROR(INDEX('Offer Statistics'!F$2:F$500,MATCH(1,(CityU!$A7='Offer Statistics'!$B$2:$B$500)*(CityU!$AB$2='Offer Statistics'!$C$2:$C$500),0)),"/")} -> 767 | AN7: {=IFERROR(INDEX('Offer Statistics'!G$2:G$500,MATCH(1,(CityU!$A7='Offer Statistics'!$B$2:$B$500)*(CityU!$AB$2='Offer Statistics'!$C$2:$C$500),0)),"/")} -> 911 | AO7: {=IFERROR(INDEX('Offer Statistics'!H$2:H$500,MATCH(1,(CityU!$A7='Offer Statistics'!$B$2:$B$500)*(CityU!$AB$2='Offer Statistics'!$C$2:$C$500),0)),"/")} -> 573 | AQ7: =A7 -> JS1012
A8: ='Reference Score Calculation'!B19 -> JS1013 | B8: ='Reference Score Calculation'!D19 -> 商學院 | C8: ='Reference Score Calculation'!E19 -> 工商管理學士(商業經濟) (特點: 經濟理論 / 國際經濟 / 經濟與商業預測 / 定量分析) | D8: ='Reference Score Calculation'!S19 -> BBABE | E8: ='Reference Score Calculation'!AC19 -> Best 5 | F8: ='Reference Score Calculation'!F19 -> Best 5 | G8: ='Reference Score Calculation'!I19 -> 20.5 | H8: ='Reference Score Calculation'!J19 -> 20.5 | I8: =計分版!J42 -> 3.3e-09 | J8: =IFERROR(IF(J$1="差距(Median)",I8-G8,IF(J$1="差距(LQ)",I8-H8)),"/") -> -20.5 | K8: =IFERROR(IF(J$1="差距(Median)",(I8-G8)/I8,IF(J$1="差距(LQ)",(I8-H8)/I8)),"/") -> -6.2121212e+09 | L8: ='Reference Score Calculation'!U19 -> 31 | M8: =入學要求!Z28 -> 0 | O8: =入學要求!L28 -> 3 | P8: =入學要求!M28 -> 3 | Q8: =入學要求!N28 -> 3 | R8: =入學要求!O28 -> 1 | S8: =入學要求!P28 -> 3 | T8: =入學要求!Q28 -> 3 | U8: =入學要求!S28 -> 0 | V8: =入學要求!T28 -> 0 | W8: =入學要求!U28 -> 0 | X8: =入學要求!V28 -> 0 | Y8: =入學要求!W28 -> 0 | Z8: =入學要求!X28 -> 0 | AA8: =IFERROR(ROUND(AK8/AD8,2),"/") -> 14.88 | AC8: {=IFERROR(INDEX('Offer Statistics'!$Q$2:$Q$500,MATCH(1,(CityU!$A8='Offer Statistics'!$B$2:$B$500)*(CityU!$AB$2='Offer Statistics'!$K$2:$K$500),0)),"/")} -> 32 | AD8: {=IFERROR(INDEX('Offer Statistics'!L$2:L$500,MATCH(1,(CityU!$A8='Offer Statistics'!$B$2:$B$500)*(CityU!$AB$2='Offer Statistics'!$K$2:$K$500),0)),"/")} -> 32 | AE8: {=IFERROR(INDEX('Offer Statistics'!M$2:M$500,MATCH(1,(CityU!$A8='Offer Statistics'!$B$2:$B$500)*(CityU!$AB$2='Offer Statistics'!$K$2:$K$500),0)),"/")} -> 0 | AF8: {=IFERROR(INDEX('Offer Statistics'!N$2:N$500,MATCH(1,(CityU!$A8='Offer Statistics'!$B$2:$B$500)*(CityU!$AB$2='Offer Statistics'!$K$2:$K$500),0)),"/")} -> 0 | AG8: {=IFERROR(INDEX('Offer Statistics'!O$2:O$500,MATCH(1,(CityU!$A8='Offer Statistics'!$B$2:$B$500)*(CityU!$AB$2='Offer Statistics'!$K$2:$K$500),0)),"/")} -> 0 | AH8: {=IFERROR(INDEX('Offer Statistics'!P$2:P$500,MATCH(1,(CityU!$A8='Offer Statistics'!$B$2:$B$500)*(CityU!$AB$2='Offer Statistics'!$K$2:$K$500),0)),"/")} -> 0 | AJ8: {=IFERROR(INDEX('Offer Statistics'!$I$2:$I$500,MATCH(1,(CityU!$A8='Offer Statistics'!$B$2:$B$500)*(CityU!$AB$2='Offer Statistics'!$C$2:$C$500),0)),"/")} -> 3752 | AK8: {=IFERROR(INDEX('Offer Statistics'!D$2:D$500,MATCH(1,(CityU!$A8='Offer Statistics'!$B$2:$B$500)*(CityU!$AB$2='Offer Statistics'!$C$2:$C$500),0)),"/")} -> 476 | AL8: {=IFERROR(INDEX('Offer Statistics'!E$2:E$500,MATCH(1,(CityU!$A8='Offer Statistics'!$B$2:$B$500)*(CityU!$AB$2='Offer Statistics'!$C$2:$C$500),0)),"/")} -> 633 | AM8: {=IFERROR(INDEX('Offer Statistics'!F$2:F$500,MATCH(1,(CityU!$A8='Offer Statistics'!$B$2:$B$500)*(CityU!$AB$2='Offer Statistics'!$C$2:$C$500),0)),"/")} -> 965 | AN8: {=IFERROR(INDEX('Offer Statistics'!G$2:G$500,MATCH(1,(CityU!$A8='Offer Statistics'!$B$2:$B$500)*(CityU!$AB$2='Offer Statistics'!$C$2:$C$500),0)),"/")} -> 972 | AO8: {=IFERROR(INDEX('Offer Statistics'!H$2:H$500,MATCH(1,(CityU!$A8='Offer Statistics'!$B$2:$B$500)*(CityU!$AB$2='Offer Statistics'!$C$2:$C$500),0)),"/")} -> 706 | AQ8: =A8 -> JS1013
A9: ='Reference Score Calculation'!B20 -> JS1014 | B9: ='Reference Score Calculation'!D20 -> 商學院 | C9: ='Reference Score Calculation'!E20 -> 工商管理學士(金融) (特點: 投資分析 / 金融市場 / 公司金融/ 風險管理 / 交易室工作坊) | D9: ='Reference Score Calculation'!S20 -> BBAFIN | E9: ='Reference Score Calculation'!AC20 -> Best 5 | F9: ='Reference Score Calculation'!F20 -> Best 5 | G9: ='Reference Score Calculation'!I20 -> 20.5 | H9: ='Reference Score Calculation'!J20 -> 20.5 | I9: =計分版!J43 -> 3.3e-09 | J9: =IFERROR(IF(J$1="差距(Median)",I9-G9,IF(J$1="差距(LQ)",I9-H9)),"/") -> -20.5 | K9: =IFERROR(IF(J$1="差距(Median)",(I9-G9)/I9,IF(J$1="差距(LQ)",(I9-H9)/I9)),"/") -> -6.2121212e+09 | L9: ='Reference Score Calculation'!U20 -> 96 | M9: =入學要求!Z29 -> 0 | O9: =入學要求!L29 -> 3 | P9: =入學要求!M29 -> 3 | Q9: =入學要求!N29 -> 3 | R9: =入學要求!O29 -> 1 | S9: =入學要求!P29 -> 3 | T9: =入學要求!Q29 -> 3 | U9: =入學要求!S29 -> 0 | V9: =入學要求!T29 -> 0 | W9: =入學要求!U29 -> 0 | X9: =入學要求!V29 -> 0 | Y9: =入學要求!W29 -> 0 | Z9: =入學要求!X29 -> 0 | AA9: =IFERROR(ROUND(AK9/AD9,2),"/") -> 7.41 | AC9: {=IFERROR(INDEX('Offer Statistics'!$Q$2:$Q$500,MATCH(1,(CityU!$A9='Offer Statistics'!$B$2:$B$500)*(CityU!$AB$2='Offer Statistics'!$K$2:$K$500),0)),"/")} -> 102 | AD9: {=IFERROR(INDEX('Offer Statistics'!L$2:L$500,MATCH(1,(CityU!$A9='Offer Statistics'!$B$2:$B$500)*(CityU!$AB$2='Offer Statistics'!$K$2:$K$500),0)),"/")} -> 102 | AE9: {=IFERROR(INDEX('Offer Statistics'!M$2:M$500,MATCH(1,(CityU!$A9='Offer Statistics'!$B$2:$B$500)*(CityU!$AB$2='Offer Statistics'!$K$2:$K$500),0)),"/")} -> 0 | AF9: {=IFERROR(INDEX('Offer Statistics'!N$2:N$500,MATCH(1,(CityU!$A9='Offer Statistics'!$B$2:$B$500)*(CityU!$AB$2='Offer Statistics'!$K$2:$K$500),0)),"/")} -> 0 | AG9: {=IFERROR(INDEX('Offer Statistics'!O$2:O$500,MATCH(1,(CityU!$A9='Offer Statistics'!$B$2:$B$500)*(CityU!$AB$2='Offer Statistics'!$K$2:$K$500),0)),"/")} -> 0 | AH9: {=IFERROR(INDEX('Offer Statistics'!P$2:P$500,MATCH(1,(CityU!$A9='Offer Statistics'!$B$2:$B$500)*(CityU!$AB$2='Offer Statistics'!$K$2:$K$500),0)),"/")} -> 0 | AJ9: {=IFERROR(INDEX('Offer Statistics'!$I$2:$I$500,MATCH(1,(CityU!$A9='Offer Statistics'!$B$2:$B$500)*(CityU!$AB$2='Offer Statistics'!$C$2:$C$500),0)),"/")} -> 4249 | AK9: {=IFERROR(INDEX('Offer Statistics'!D$2:D$500,MATCH(1,(CityU!$A9='Offer Statistics'!$B$2:$B$500)*(CityU!$AB$2='Offer Statistics'!$C$2:$C$500),0)),"/")} -> 756 | AL9: {=IFERROR(INDEX('Offer Statistics'!E$2:E$500,MATCH(1,(CityU!$A9='Offer Statistics'!$B$2:$B$500)*(CityU!$AB$2='Offer Statistics'!$C$2:$C$500),0)),"/")} -> 863 | AM9: {=IFERROR(INDEX('Offer Statistics'!F$2:F$500,MATCH(1,(CityU!$A9='Offer Statistics'!$B$2:$B$500)*(CityU!$AB$2='Offer Statistics'!$C$2:$C$500),0)),"/")} -> 953 | AN9: {=IFERROR(INDEX('Offer Statistics'!G$2:G$500,MATCH(1,(CityU!$A9='Offer Statistics'!$B$2:$B$500)*(CityU!$AB$2='Offer Statistics'!$C$2:$C$500),0)),"/")} -> 999 | AO9: {=IFERROR(INDEX('Offer Statistics'!H$2:H$500,MATCH(1,(CityU!$A9='Offer Statistics'!$B$2:$B$500)*(CityU!$AB$2='Offer Statistics'!$C$2:$C$500),0)),"/")} -> 678 | AQ9: =A9 -> JS1014
A10: ='Reference Score Calculation'!B21 -> JS1017 | B10: ='Reference Score Calculation'!D21 -> 商學院 | C10: ='Reference Score Calculation'!E21 -> 資訊系統學 [主修: 工商管理學士(環球商業系統管理) 、工商管理學士(資訊管理)] | D10: ='Reference Score Calculation'!S21 -> IS | E10: ='Reference Score Calculation'!AC21 -> 3C2X | F10: ='Reference Score Calculation'!F21 -> 3C2X | G10: ='Reference Score Calculation'!I21 -> 20.5 | H10: ='Reference Score Calculation'!J21 -> 19.5 | I10: =計分版!J44 -> 2.3e-09 | J10: =IFERROR(IF(J$1="差距(Median)",I10-G10,IF(J$1="差距(LQ)",I10-H10)),"/") -> -20.5 | K10: =IFERROR(IF(J$1="差距(Median)",(I10-G10)/I10,IF(J$1="差距(LQ)",(I10-H10)/I10)),"/") -> -8.9130435e+09 | L10: ='Reference Score Calculation'!U21 -> 62 | M10: =入學要求!Z30 -> 0 | O10: =入學要求!L30 -> 3 | P10: =入學要求!M30 -> 3 | Q10: =入學要求!N30 -> 3 | R10: =入學要求!O30 -> 1 | S10: =入學要求!P30 -> 3 | T10: =入學要求!Q30 -> 3 | U10: =入學要求!S30 -> 0 | V10: =入學要求!T30 -> 0 | W10: =入學要求!U30 -> 0 | X10: =入學要求!V30 -> 0 | Y10: =入學要求!W30 -> 0 | Z10: =入學要求!X30 -> 0 | AA10: =IFERROR(ROUND(AK10/AD10,2),"/") -> 5.96 | AC10: {=IFERROR(INDEX('Offer Statistics'!$Q$2:$Q$500,MATCH(1,(CityU!$A10='Offer Statistics'!$B$2:$B$500)*(CityU!$AB$2='Offer Statistics'!$K$2:$K$500),0)),"/")} -> 59 | AD10: {=IFERROR(INDEX('Offer Statistics'!L$2:L$500,MATCH(1,(CityU!$A10='Offer Statistics'!$B$2:$B$500)*(CityU!$AB$2='Offer Statistics'!$K$2:$K$500),0)),"/")} -> 54 | AE10: {=IFERROR(INDEX('Offer Statistics'!M$2:M$500,MATCH(1,(CityU!$A10='Offer Statistics'!$B$2:$B$500)*(CityU!$AB$2='Offer Statistics'!$K$2:$K$500),0)),"/")} -> 4 | AF10: {=IFERROR(INDEX('Offer Statistics'!N$2:N$500,MATCH(1,(CityU!$A10='Offer Statistics'!$B$2:$B$500)*(CityU!$AB$2='Offer Statistics'!$K$2:$K$500),0)),"/")} -> 0 | AG10: {=IFERROR(INDEX('Offer Statistics'!O$2:O$500,MATCH(1,(CityU!$A10='Offer Statistics'!$B$2:$B$500)*(CityU!$AB$2='Offer Statistics'!$K$2:$K$500),0)),"/")} -> 1 | AH10: {=IFERROR(INDEX('Offer Statistics'!P$2:P$500,MATCH(1,(CityU!$A10='Offer Statistics'!$B$2:$B$500)*(CityU!$AB$2='Offer Statistics'!$K$2:$K$500),0)),"/")} -> 0 | AJ10: {=IFERROR(INDEX('Offer Statistics'!$I$2:$I$500,MATCH(1,(CityU!$A10='Offer Statistics'!$B$2:$B$500)*(CityU!$AB$2='Offer Statistics'!$C$2:$C$500),0)),"/")} -> 1895 | AK10: {=IFERROR(INDEX('Offer Statistics'!D$2:D$500,MATCH(1,(CityU!$A10='Offer Statistics'!$B$2:$B$500)*(CityU!$AB$2='Offer Statistics'!$C$2:$C$500),0)),"/")} -> 322 | AL10: {=IFERROR(INDEX('Offer Statistics'!E$2:E$500,MATCH(1,(CityU!$A10='Offer Statistics'!$B$2:$B$500)*(CityU!$AB$2='Offer Statistics'!$C$2:$C$500),0)),"/")} -> 269 | AM10: {=IFERROR(INDEX('Offer Statistics'!F$2:F$500,MATCH(1,(CityU!$A10='Offer Statistics'!$B$2:$B$500)*(CityU!$AB$2='Offer Statistics'!$C$2:$C$500),0)),"/")} -> 432 | AN10: {=IFERROR(INDEX('Offer Statistics'!G$2:G$500,MATCH(1,(CityU!$A10='Offer Statistics'!$B$2:$B$500)*(CityU!$AB$2='Offer Statistics'!$C$2:$C$500),0)),"/")} -> 508 | AO10: {=IFERROR(INDEX('Offer Statistics'!H$2:H$500,MATCH(1,(CityU!$A10='Offer Statistics'!$B$2:$B$500)*(CityU!$AB$2='Offer Statistics'!$C$2:$C$500),0)),"/")} -> 364 | AQ10: =A10 -> JS1017
A11: ='Reference Score Calculation'!B22 -> JS1018 | B11: ='Reference Score Calculation'!D22 -> 商學院 | C11: ='Reference Score Calculation'!E22 -> 工商管理學士(環球商業系統管理) (特點: 智能科技 / 環球商業 / 海外及内地交流) | D11: ='Reference Score Calculation'!S22 -> BBAGBSM | E11: ='Reference Score Calculation'!AC22 -> 3C2X | F11: ='Reference Score Calculation'!F22 -> 3C2X | G11: ='Reference Score Calculation'!I22 -> 22 | H11: ='Reference Score Calculation'!J22 -> 22 | I11: =計分版!J45 -> 2.3e-09 | J11: =IFERROR(IF(J$1="差距(Median)",I11-G11,IF(J$1="差距(LQ)",I11-H11)),"/") -> -22 | K11: =IFERROR(IF(J$1="差距(Median)",(I11-G11)/I11,IF(J$1="差距(LQ)",(I11-H11)/I11)),"/") -> -9.5652174e+09 | L11: ='Reference Score Calculation'!U22 -> 10 | M11: =入學要求!Z31 -> 0 | O11: =入學要求!L31 -> 3 | P11: =入學要求!M31 -> 3 | Q11: =入學要求!N31 -> 3 | R11: =入學要求!O31 -> 1 | S11: =入學要求!P31 -> 3 | T11: =入學要求!Q31 -> 3 | U11: =入學要求!S31 -> 0 | V11: =入學要求!T31 -> 0 | W11: =入學要求!U31 -> 0 | X11: =入學要求!V31 -> 0 | Y11: =入學要求!W31 -> 0 | Z11: =入學要求!X31 -> 0 | AA11: =IFERROR(ROUND(AK11/AD11,2),"/") -> 10.5 | AC11: {=IFERROR(INDEX('Offer Statistics'!$Q$2:$Q$500,MATCH(1,(CityU!$A11='Offer Statistics'!$B$2:$B$500)*(CityU!$AB$2='Offer Statistics'!$K$2:$K$500),0)),"/")} -> 8 | AD11: {=IFERROR(INDEX('Offer Statistics'!L$2:L$500,MATCH(1,(CityU!$A11='Offer Statistics'!$B$2:$B$500)*(CityU!$AB$2='Offer Statistics'!$K$2:$K$500),0)),"/")} -> 6 | AE11: {=IFERROR(INDEX('Offer Statistics'!M$2:M$500,MATCH(1,(CityU!$A11='Offer Statistics'!$B$2:$B$500)*(CityU!$AB$2='Offer Statistics'!$K$2:$K$500),0)),"/")} -> 2 | AF11: {=IFERROR(INDEX('Offer Statistics'!N$2:N$500,MATCH(1,(CityU!$A11='Offer Statistics'!$B$2:$B$500)*(CityU!$AB$2='Offer Statistics'!$K$2:$K$500),0)),"/")} -> 0 | AG11: {=IFERROR(INDEX('Offer Statistics'!O$2:O$500,MATCH(1,(CityU!$A11='Offer Statistics'!$B$2:$B$500)*(CityU!$AB$2='Offer Statistics'!$K$2:$K$500),0)),"/")} -> 0 | AH11: {=IFERROR(INDEX('Offer Statistics'!P$2:P$500,MATCH(1,(CityU!$A11='Offer Statistics'!$B$2:$B$500)*(CityU!$AB$2='Offer Statistics'!$K$2:$K$500),0)),"/")} -> 0 | AJ11: {=IFERROR(INDEX('Offer Statistics'!$I$2:$I$500,MATCH(1,(CityU!$A11='Offer Statistics'!$B$2:$B$500)*(CityU!$AB$2='Offer Statistics'!$C$2:$C$500),0)),"/")} -> 1366 | AK11: {=IFERROR(INDEX('Offer Statistics'!D$2:D$500,MATCH(1,(CityU!$A11='Offer Statistics'!$B$2:$B$500)*(CityU!$AB$2='Offer Statistics'!$C$2:$C$500),0)),"/")} -> 63 | AL11: {=IFERROR(INDEX('Offer Statistics'!E$2:E$500,MATCH(1,(CityU!$A11='Offer Statistics'!$B$2:$B$500)*(CityU!$AB$2='Offer Statistics'!$C$2:$C$500),0)),"/")} -> 173 | AM11: {=IFERROR(INDEX('Offer Statistics'!F$2:F$500,MATCH(1,(CityU!$A11='Offer Statistics'!$B$2:$B$500)*(CityU!$AB$2='Offer Statistics'!$C$2:$C$500),0)),"/")} -> 334 | AN11: {=IFERROR(INDEX('Offer Statistics'!G$2:G$500,MATCH(1,(CityU!$A11='Offer Statistics'!$B$2:$B$500)*(CityU!$AB$2='Offer Statistics'!$C$2:$C$500),0)),"/")} -> 456 | AO11: {=IFERROR(INDEX('Offer Statistics'!H$2:H$500,MATCH(1,(CityU!$A11='Offer Statistics'!$B$2:$B$500)*(CityU!$AB$2='Offer Statistics'!$C$2:$C$500),0)),"/")} -> 340 | AQ11: =A11 -> JS1018
A12: ='Reference Score Calculation'!B23 -> JS1019 | B12: ='Reference Score Calculation'!D23 -> 商學院 | C12: ='Reference Score Calculation'!E23 -> 工商管理學士(資訊管理) (專修: 商務智能 / 信息系統審計 / 互聯網服務及社交網絡 / 數據信息學) | D12: ='Reference Score Calculation'!S23 -> BBAIFMG | E12: ='Reference Score Calculation'!AC23 -> 3C2X | F12: ='Reference Score Calculation'!F23 -> 3C2X | G12: ='Reference Score Calculation'!I23 -> 20.5 | H12: ='Reference Score Calculation'!J23 -> 19.5 | I12: =計分版!J46 -> 2.3e-09 | J12: =IFERROR(IF(J$1="差距(Median)",I12-G12,IF(J$1="差距(LQ)",I12-H12)),"/") -> -20.5 | K12: =IFERROR(IF(J$1="差距(Median)",(I12-G12)/I12,IF(J$1="差距(LQ)",(I12-H12)/I12)),"/") -> -8.9130435e+09 | L12: ='Reference Score Calculation'!U23 -> 10 | M12: =入學要求!Z32 -> 0 | O12: =入學要求!L32 -> 3 | P12: =入學要求!M32 -> 3 | Q12: =入學要求!N32 -> 3 | R12: =入學要求!O32 -> 1 | S12: =入學要求!P32 -> 3 | T12: =入學要求!Q32 -> 3 | U12: =入學要求!S32 -> 0 | V12: =入學要求!T32 -> 0 | W12: =入學要求!U32 -> 0 | X12: =入學要求!V32 -> 0 | Y12: =入學要求!W32 -> 0 | Z12: =入學要求!X32 -> 0 | AA12: =IFERROR(ROUND(AK12/AD12,2),"/") -> 22 | AC12: {=IFERROR(INDEX('Offer Statistics'!$Q$2:$Q$500,MATCH(1,(CityU!$A12='Offer Statistics'!$B$2:$B$500)*(CityU!$AB$2='Offer Statistics'!$K$2:$K$500),0)),"/")} -> 7 | AD12: {=IFERROR(INDEX('Offer Statistics'!L$2:L$500,MATCH(1,(CityU!$A12='Offer Statistics'!$B$2:$B$500)*(CityU!$AB$2='Offer Statistics'!$K$2:$K$500),0)),"/")} -> 3 | AE12: {=IFERROR(INDEX('Offer Statistics'!M$2:M$500,MATCH(1,(CityU!$A12='Offer Statistics'!$B$2:$B$500)*(CityU!$AB$2='Offer Statistics'!$K$2:$K$500),0)),"/")} -> 2 | AF12: {=IFERROR(INDEX('Offer Statistics'!N$2:N$500,MATCH(1,(CityU!$A12='Offer Statistics'!$B$2:$B$500)*(CityU!$AB$2='Offer Statistics'!$K$2:$K$500),0)),"/")} -> 2 | AG12: {=IFERROR(INDEX('Offer Statistics'!O$2:O$500,MATCH(1,(CityU!$A12='Offer Statistics'!$B$2:$B$500)*(CityU!$AB$2='Offer Statistics'!$K$2:$K$500),0)),"/")} -> 0 | AH12: {=IFERROR(INDEX('Offer Statistics'!P$2:P$500,MATCH(1,(CityU!$A12='Offer Statistics'!$B$2:$B$500)*(CityU!$AB$2='Offer Statistics'!$K$2:$K$500),0)),"/")} -> 0 | AJ12: {=IFERROR(INDEX('Offer Statistics'!$I$2:$I$500,MATCH(1,(CityU!$A12='Offer Statistics'!$B$2:$B$500)*(CityU!$AB$2='Offer Statistics'!$C$2:$C$500),0)),"/")} -> 1365 | AK12: {=IFERROR(INDEX('Offer Statistics'!D$2:D$500,MATCH(1,(CityU!$A12='Offer Statistics'!$B$2:$B$500)*(CityU!$AB$2='Offer Statistics'!$C$2:$C$500),0)),"/")} -> 66 | AL12: {=IFERROR(INDEX('Offer Statistics'!E$2:E$500,MATCH(1,(CityU!$A12='Offer Statistics'!$B$2:$B$500)*(CityU!$AB$2='Offer Statistics'!$C$2:$C$500),0)),"/")} -> 157 | AM12: {=IFERROR(INDEX('Offer Statistics'!F$2:F$500,MATCH(1,(CityU!$A12='Offer Statistics'!$B$2:$B$500)*(CityU!$AB$2='Offer Statistics'!$C$2:$C$500),0)),"/")} -> 312 | AN12: {=IFERROR(INDEX('Offer Statistics'!G$2:G$500,MATCH(1,(CityU!$A12='Offer Statistics'!$B$2:$B$500)*(CityU!$AB$2='Offer Statistics'!$C$2:$C$500),0)),"/")} -> 488 | AO12: {=IFERROR(INDEX('Offer Statistics'!H$2:H$500,MATCH(1,(CityU!$A12='Offer Statistics'!$B$2:$B$500)*(CityU!$AB$2='Offer Statistics'!$C$2:$C$500),0)),"/")} -> 342 | AQ12: =A12 -> JS1019
A13: ='Reference Score Calculation'!B24 -> JS1025 | B13: ='Reference Score Calculation'!D24 -> 商學院 | C13: ='Reference Score Calculation'!E24 -> 決策分析及營運學 [主修: 工商管理學士(商業決策分析) / 工商管理學士(環球營運管理)] | D13: ='Reference Score Calculation'!S24 -> DAO | E13: ='Reference Score Calculation'!AC24 -> 3C2X | F13: ='Reference Score Calculation'!F24 -> 3C2X | G13: ='Reference Score Calculation'!I24 -> 20 | H13: ='Reference Score Calculation'!J24 -> 19.5 | I13: =計分版!J47 -> 2.3e-09 | J13: =IFERROR(IF(J$1="差距(Median)",I13-G13,IF(J$1="差距(LQ)",I13-H13)),"/") -> -20 | K13: =IFERROR(IF(J$1="差距(Median)",(I13-G13)/I13,IF(J$1="差距(LQ)",(I13-H13)/I13)),"/") -> -8.6956522e+09 | L13: ='Reference Score Calculation'!U24 -> 24 | M13: =入學要求!Z33 -> 0 | O13: =入學要求!L33 -> 3 | P13: =入學要求!M33 -> 3 | Q13: =入學要求!N33 -> 3 | R13: =入學要求!O33 -> 1 | S13: =入學要求!P33 -> 3 | T13: =入學要求!Q33 -> 3 | U13: =入學要求!S33 -> 0 | V13: =入學要求!T33 -> 0 | W13: =入學要求!U33 -> 0 | X13: =入學要求!V33 -> 0 | Y13: =入學要求!W33 -> 0 | Z13: =入學要求!X33 -> 0 | AA13: =IFERROR(ROUND(AK13/AD13,2),"/") -> 18.91 | AC13: {=IFERROR(INDEX('Offer Statistics'!$Q$2:$Q$500,MATCH(1,(CityU!$A13='Offer Statistics'!$B$2:$B$500)*(CityU!$AB$2='Offer Statistics'!$K$2:$K$500),0)),"/")} -> 24 | AD13: {=IFERROR(INDEX('Offer Statistics'!L$2:L$500,MATCH(1,(CityU!$A13='Offer Statistics'!$B$2:$B$500)*(CityU!$AB$2='Offer Statistics'!$K$2:$K$500),0)),"/")} -> 22 | AE13: {=IFERROR(INDEX('Offer Statistics'!M$2:M$500,MATCH(1,(CityU!$A13='Offer Statistics'!$B$2:$B$500)*(CityU!$AB$2='Offer Statistics'!$K$2:$K$500),0)),"/")} -> 1 | AF13: {=IFERROR(INDEX('Offer Statistics'!N$2:N$500,MATCH(1,(CityU!$A13='Offer Statistics'!$B$2:$B$500)*(CityU!$AB$2='Offer Statistics'!$K$2:$K$500),0)),"/")} -> 1 | AG13: {=IFERROR(INDEX('Offer Statistics'!O$2:O$500,MATCH(1,(CityU!$A13='Offer Statistics'!$B$2:$B$500)*(CityU!$AB$2='Offer Statistics'!$K$2:$K$500),0)),"/")} -> 0 | AH13: {=IFERROR(INDEX('Offer Statistics'!P$2:P$500,MATCH(1,(CityU!$A13='Offer Statistics'!$B$2:$B$500)*(CityU!$AB$2='Offer Statistics'!$K$2:$K$500),0)),"/")} -> 0 | AJ13: {=IFERROR(INDEX('Offer Statistics'!$I$2:$I$500,MATCH(1,(CityU!$A13='Offer Statistics'!$B$2:$B$500)*(CityU!$AB$2='Offer Statistics'!$C$2:$C$500),0)),"/")} -> 2296 | AK13: {=IFERROR(INDEX('Offer Statistics'!D$2:D$500,MATCH(1,(CityU!$A13='Offer Statistics'!$B$2:$B$500)*(CityU!$AB$2='Offer Statistics'!$C$2:$C$500),0)),"/")} -> 416 | AL13: {=IFERROR(INDEX('Offer Statistics'!E$2:E$500,MATCH(1,(CityU!$A13='Offer Statistics'!$B$2:$B$500)*(CityU!$AB$2='Offer Statistics'!$C$2:$C$500),0)),"/")} -> 382 | AM13: {=IFERROR(INDEX('Offer Statistics'!F$2:F$500,MATCH(1,(CityU!$A13='Offer Statistics'!$B$2:$B$500)*(CityU!$AB$2='Offer Statistics'!$C$2:$C$500),0)),"/")} -> 527 | AN13: {=IFERROR(INDEX('Offer Statistics'!G$2:G$500,MATCH(1,(CityU!$A13='Offer Statistics'!$B$2:$B$500)*(CityU!$AB$2='Offer Statistics'!$C$2:$C$500),0)),"/")} -> 552 | AO13: {=IFERROR(INDEX('Offer Statistics'!H$2:H$500,MATCH(1,(CityU!$A13='Offer Statistics'!$B$2:$B$500)*(CityU!$AB$2='Offer Statistics'!$C$2:$C$500),0)),"/")} -> 419 | AQ13: =A13 -> JS1025
