Workbook

Sheet Table 1
A1: JUPAS Code: JS3010 | AB1: {=_xlfn._xlws.FILTER(A1:Z1,A1:Z1<>"","")} -> JUPAS Code: JS3010 | AD1: {=IF(LEFT(AB1:AB1640,10)="JUPAS Code",RIGHT(AB1:AB1640,6),"")} -> JS3010 | AE1: {=IF(LEFT(AB1:AB1640,15)="Programme Title",SUBSTITUTE(AB1:AB1640,"Programme Title: ",""),"")} | AF1: {=IF(AD1="","",SUMPRODUCT(IF(LEFT($AD$1:AD1,2)="JS",1,0)))} -> 1 | AG1: =IF(ISNUMBER(MATCH(AB1,$AV$3:$AV$18,0)),TRUE,"") | AH1: =IF(AND(AC1=10,AG1=TRUE),AB1,"") | AI1: =IF(AH1="","",MAX($AF$1:$AF1)) | AJ1: =IF(AND(AC1=7,AG1=TRUE),AB1,"") | AK1: =IF(AJ1="","",MAX($AF$1:$AF1)) | AL1: =IF(AND(AC1=5,AG1=TRUE),AB1,"") | AM1: =IF(AL1="","",MAX($AF$1:$AF1)) | AQ1: 10 | AR1: 7 | AS1: 5
A2: Programme Title: BSc (Hons) Scheme in Biotechnology, Food Safety and Chemical Technology | AB2: {=_xlfn._xlws.FILTER(A2:Z2,A2:Z2<>"","")} -> Programme Title: BSc (Hons) Scheme in Biotechnology, Food Safety and Chemical Technology | AE2: BSc (Hons) Scheme in Biotechnology, Food Safety and Chemical Technology | AF2: {=IF(AD2="","",SUMPRODUCT(IF(LEFT($AD$1:AD2,2)="JS",1,0)))} | AG2: =IF(ISNUMBER(MATCH(AB2,$AV$3:$AV$18,0)),TRUE,"") | AH2: =IF(AND(AC2=10,AG2=TRUE),AB2,"") | AI2: =IF(AH2="","",MAX($AF$1:$AF2)) | AJ2: =IF(AND(AC2=7,AG2=TRUE),AB2,"") | AK2: =IF(AJ2="","",MAX($AF$1:$AF2)) | AL2: =IF(AND(AC2=5,AG2=TRUE),AB2,"") | AM2: =IF(AL2="","",MAX($AF$1:$AF2)) | AO2: {=_xlfn._xlws.FILTER(AD1:AD1640,AD1:AD1640<>"","")} -> JS3010 | AP2: {=_xlfn._xlws.FILTER(AE1:AE1640,AE1:AE1640<>"","")} -> BSc (Hons) Scheme in Biotechnology, Food Safety and Chemical Technology | AQ2: {=_xlfn.TEXTJOIN(", ",TRUE,_xlfn._xlws.FILTER($AH$1:$AH$1640,$AI$1:$AI$1640=ROW()-1,""))} -> BIO, CHEM, ENG, MATH | AR2: {=_xlfn.TEXTJOIN(", ",TRUE,_xlfn._xlws.FILTER($AJ$1:$AJ$1640,$AK$1:$AK$1640=ROW()-1,""))} -> 中文, 通, M2, PHY | AS2: {=_xlfn.TEXTJOIN(", ",TRUE,_xlfn._xlws.FILTER($AL$1:$AL$1640,$AM$1:$AM$1640=ROW()-1,""))} -> BAFS, 中史, ECON, GEOG, HMSC, HIST, ICT, VA
A3: Category A: Core and Elective Subjects | AB3: {=_xlfn._xlws.FILTER(A3:Z3,A3:Z3<>"","")} -> Category A: Core and Elective Subjects | AF3: {=IF(AD3="","",SUMPRODUCT(IF(LEFT($AD$1:AD3,2)="JS",1,0)))} | AG3: =IF(ISNUMBER(MATCH(AB3,$AV$3:$AV$18,0)),TRUE,"") | AH3: =IF(AND(AC3=10,AG3=TRUE),AB3,"") | AI3: =IF(AH3="","",MAX($AF$1:$AF3)) | AJ3: =IF(AND(AC3=7,AG3=TRUE),AB3,"") | AK3: =IF(AJ3="","",MAX($AF$1:$AF3)) | AL3: =IF(AND(AC3=5,AG3=TRUE),AB3,"") | AM3: =IF(AL3="","",MAX($AF$1:$AF3)) | AO3: JS3020 | AP3: BSc (Hons) Scheme in Data Science | AQ3: {=_xlfn.TEXTJOIN(", ",TRUE,_xlfn._xlws.FILTER($AH$1:$AH$1640,$AI$1:$AI$1640=ROW()-1,""))} -> ENG, MATH | AR3: {=_xlfn.TEXTJOIN(", ",TRUE,_xlfn._xlws.FILTER($AJ$1:$AJ$1640,$AK$1:$AK$1640=ROW()-1,""))} -> BIO, BAFS, CHEM, 中文, ECON, ICT, 通, M2, PHY | AS3: {=_xlfn.TEXTJOIN(", ",TRUE,_xlfn._xlws.FILTER($AL$1:$AL$1640,$AM$1:$AM$1640=ROW()-1,""))} -> 中史, GEOG, HMSC, HIST, VA | AV3: BIO
A4: Subject Name | C4: Subject Weighting for 2023/24 Admission Exercise * | AB4: {=_xlfn._xlws.FILTER(A4:Z4,A4:Z4<>"","")} -> Subject Name | AC4: Subject Weighting for 2023/24 Admission Exercise * | AF4: {=IF(AD4="","",SUMPRODUCT(IF(LEFT($AD$1:AD4,2)="JS",1,0)))} | AG4: =IF(ISNUMBER(MATCH(AB4,$AV$3:$AV$18,0)),TRUE,"") | AH4: =IF(AND(AC4=10,AG4=TRUE),AB4,"") | AI4: =IF(AH4="","",MAX($AF$1:$AF4)) | AJ4: =IF(AND(AC4=7,AG4=TRUE),AB4,"") | AK4: =IF(AJ4="","",MAX($AF$1:$AF4)) | AL4: =IF(AND(AC4=5,AG4=TRUE),AB4,"") | AM4: =IF(AL4="","",MAX($AF$1:$AF4)) | AO4: JS3050 | AP4: BA (Hons) Scheme in Fashion | AQ4: {=_xlfn.TEXTJOIN(", ",TRUE,_xlfn._xlws.FILTER($AH$1:$AH$1640,$AI$1:$AI$1640=ROW()-1,""))} -> ECON, VA | AR4: {=_xlfn.TEXTJOIN(", ",TRUE,_xlfn._xlws.FILTER($AJ$1:$AJ$1640,$AK$1:$AK$1640=ROW()-1,""))} -> 中文, ENG, 通, MATH, M2 | AS4: {=_xlfn.TEXTJOIN(", ",TRUE,_xlfn._xlws.FILTER($AL$1:$AL$1640,$AM$1:$AM$1640=ROW()-1,""))} -> BIO, BAFS, CHEM, 中史, GEOG, HMSC, HIST, ICT, PHY | AV4: BAFS
A5: BIO | C5: 10 | AB5: {=_xlfn._xlws.FILTER(A5:Z5,A5:Z5<>"","")} -> BIO | AC5: 10 | AF5: {=IF(AD5="","",SUMPRODUCT(IF(LEFT($AD$1:AD5,2)="JS",1,0)))} | AG5: =IF(ISNUMBER(MATCH(AB5,$AV$3:$AV$18,0)),TRUE,"") -> TRUE | AH5: =IF(AND(AC5=10,AG5=TRUE),AB5,"") -> BIO | AI5: =IF(AH5="","",MAX($AF$1:$AF5)) -> 1 | AJ5: =IF(AND(AC5=7,AG5=TRUE),AB5,"") | AK5: =IF(AJ5="","",MAX($AF$1:$AF5)) | AL5: =IF(AND(AC5=5,AG5=TRUE),AB5,"") | AM5: =IF(AL5="","",MAX($AF$1:$AF5)) | AO5: JS3060 | AP5: BBA (Hons) Scheme in Accounting and Finance | AQ5: {=_xlfn.TEXTJOIN(", ",TRUE,_xlfn._xlws.FILTER($AH$1:$AH$1640,$AI$1:$AI$1640=ROW()-1,""))} -> ENG, MATH | AR5: {=_xlfn.TEXTJOIN(", ",TRUE,_xlfn._xlws.FILTER($AJ$1:$AJ$1640,$AK$1:$AK$1640=ROW()-1,""))} -> BIO, BAFS, CHEM, 中史, 中文, ECON, GEOG, HIST, 通, M2, PHY | AS5: {=_xlfn.TEXTJOIN(", ",TRUE,_xlfn._xlws.FILTER($AL$1:$AL$1640,$AM$1:$AM$1640=ROW()-1,""))} -> HMSC, ICT, VA | AV5: CHEM
A6: BAFS | C6: 5 | AB6: {=_xlfn._xlws.FILTER(A6:Z6,A6:Z6<>"","")} -> BAFS | AC6: 5 | AF6: {=IF(AD6="","",SUMPRODUCT(IF(LEFT($AD$1:AD6,2)="JS",1,0)))} | AG6: =IF(ISNUMBER(MATCH(AB6,$AV$3:$AV$18,0)),TRUE,"") -> TRUE | AH6: =IF(AND(AC6=10,AG6=TRUE),AB6,"") | AI6: =IF(AH6="","",MAX($AF$1:$AF6)) | AJ6: =IF(AND(AC6=7,AG6=TRUE),AB6,"") | AK6: =IF(AJ6="","",MAX($AF$1:$AF6)) | AL6: =IF(AND(AC6=5,AG6=TRUE),AB6,"") -> BAFS | AM6: =IF(AL6="","",MAX($AF$1:$AF6)) -> 1 | AO6: JS3070 | AP6: BBA (Hons) Scheme in Aviation, Maritime and Supply Chain Management | AQ6: {=_xlfn.TEXTJOIN(", ",TRUE,_xlfn._xlws.FILTER($AH$1:$AH$1640,$AI$1:$AI$1640=ROW()-1,""))} -> ENG, MATH | AR6: {=_xlfn.TEXTJOIN(", ",TRUE,_xlfn._xlws.FILTER($AJ$1:$AJ$1640,$AK$1:$AK$1640=ROW()-1,""))} -> BIO, BAFS, CHEM, 中史, 中文, ECON, GEOG, HIST, 通, M2, PHY | AS6: {=_xlfn.TEXTJOIN(", ",TRUE,_xlfn._xlws.FILTER($AL$1:$AL$1640,$AM$1:$AM$1640=ROW()-1,""))} -> HMSC, ICT, VA | AV6: 中史
A7: Business, Accounting and Financial Studies (Accounting) | C7: 5 | AB7: {=_xlfn._xlws.FILTER(A7:Z7,A7:Z7<>"","")} -> Business, Accounting and Financial Studies (Accounting) | AC7: 5 | AF7: {=IF(AD7="","",SUMPRODUCT(IF(LEFT($AD$1:AD7,2)="JS",1,0)))} | AG7: =IF(ISNUMBER(MATCH(AB7,$AV$3:$AV$18,0)),TRUE,"") | AH7: =IF(AND(AC7=10,AG7=TRUE),AB7,"") | AI7: =IF(AH7="","",MAX($AF$1:$AF7)) | AJ7: =IF(AND(AC7=7,AG7=TRUE),AB7,"") | AK7: =IF(AJ7="","",MAX($AF$1:$AF7)) | AL7: =IF(AND(AC7=5,AG7=TRUE),AB7,"") | AM7: =IF(AL7="","",MAX($AF$1:$AF7)) | AO7: JS3080 | AP7: BBA (Hons) Scheme in Management and Marketing | AQ7: {=_xlfn.TEXTJOIN(", ",TRUE,_xlfn._xlws.FILTER($AH$1:$AH$1640,$AI$1:$AI$1640=ROW()-1,""))} -> ENG, MATH | AR7: {=_xlfn.TEXTJOIN(", ",TRUE,_xlfn._xlws.FILTER($AJ$1:$AJ$1640,$AK$1:$AK$1640=ROW()-1,""))} -> BIO, BAFS, CHEM, 中史, 中文, ECON, GEOG, HIST, 通, M2, PHY | AS7: {=_xlfn.TEXTJOIN(", ",TRUE,_xlfn._xlws.FILTER($AL$1:$AL$1640,$AM$1:$AM$1640=ROW()-1,""))} -> HMSC, ICT, VA | AV7: 中文
A8: Business, Accounting and Financial Studies (Business Management) | C8: 5 | AB8: {=_xlfn._xlws.FILTER(A8:Z8,A8:Z8<>"","")} -> Business, Accounting and Financial Studies (Business Management) | AC8: 5 | AF8: {=IF(AD8="","",SUMPRODUCT(IF(LEFT($AD$1:AD8,2)="JS",1,0)))} | AG8: =IF(ISNUMBER(MATCH(AB8,$AV$3:$AV$18,0)),TRUE,"") | AH8: =IF(AND(AC8=10,AG8=TRUE),AB8,"") | AI8: =IF(AH8="","",MAX($AF$1:$AF8)) | AJ8: =IF(AND(AC8=7,AG8=TRUE),AB8,"") | AK8: =IF(AJ8="","",MAX($AF$1:$AF8)) | AL8: =IF(AND(AC8=5,AG8=TRUE),AB8,"") | AM8: =IF(AL8="","",MAX($AF$1:$AF8)) | AO8: JS3100 | AP8: BSc (Hons) Scheme in Building and Real Estate | AQ8: {=_xlfn.TEXTJOIN(", ",TRUE,_xlfn._xlws.FILTER($AH$1:$AH$1640,$AI$1:$AI$1640=ROW()-1,""))} -> ENG | AR8: {=_xlfn.TEXTJOIN(", ",TRUE,_xlfn._xlws.FILTER($AJ$1:$AJ$1640,$AK$1:$AK$1640=ROW()-1,""))} -> BIO, BAFS, CHEM, 中史, 中文, ECON, GEOG, HMSC, HIST, ICT, 通, MATH, M2, PHY | AS8: {=_xlfn.TEXTJOIN(", ",TRUE,_xlfn._xlws.FILTER($AL$1:$AL$1640,$AM$1:$AM$1640=ROW()-1,""))} -> VA | AV8: 通
A9: CHEM | C9: 10 | AB9: {=_xlfn._xlws.FILTER(A9:Z9,A9:Z9<>"","")} -> CHEM | AC9: 10 | AF9: {=IF(AD9="","",SUMPRODUCT(IF(LEFT($AD$1:AD9,2)="JS",1,0)))} | AG9: =IF(ISNUMBER(MATCH(AB9,$AV$3:$AV$18,0)),TRUE,"") -> TRUE | AH9: =IF(AND(AC9=10,AG9=TRUE),AB9,"") -> CHEM | AI9: =IF(AH9="","",MAX($AF$1:$AF9)) -> 1 | AJ9: =IF(AND(AC9=7,AG9=TRUE),AB9,"") | AK9: =IF(AJ9="","",MAX($AF$1:$AF9)) | AL9: =IF(AND(AC9=5,AG9=TRUE),AB9,"") | AM9: =IF(AL9="","",MAX($AF$1:$AF9)) | AO9: JS3110 | AP9: BEng (Hons) Scheme in Building Sciences and Engineering | AQ9: {=_xlfn.TEXTJOIN(", ",TRUE,_xlfn._xlws.FILTER($AH$1:$AH$1640,$AI$1:$AI$1640=ROW()-1,""))} -> ENG, MATH, PHY | AR9: {=_xlfn.TEXTJOIN(", ",TRUE,_xlfn._xlws.FILTER($AJ$1:$AJ$1640,$AK$1:$AK$1640=ROW()-1,""))} -> BIO, BAFS, CHEM, 中文, ECON, GEOG, HMSC, ICT, 通, M2 | AS9: {=_xlfn.TEXTJOIN(", ",TRUE,_xlfn._xlws.FILTER($AL$1:$AL$1640,$AM$1:$AM$1640=ROW()-1,""))} -> 中史, HIST, VA | AV9: ECON
A10: 中史 | C10: 5 | AB10: {=_xlfn._xlws.FILTER(A10:Z10,A10:Z10<>"","")} -> 中史 | AC10: 5 | AF10: {=IF(AD10="","",SUMPRODUCT(IF(LEFT($AD$1:AD10,2)="JS",1,0)))} | AG10: =IF(ISNUMBER(MATCH(AB10,$AV$3:$AV$18,0)),TRUE,"") -> TRUE | AH10: =IF(AND(AC10=10,AG10=TRUE),AB10,"") | AI10: =IF(AH10="","",MAX($AF$1:$AF10)) | AJ10: =IF(AND(AC10=7,AG10=TRUE),AB10,"") | AK10: =IF(AJ10="","",MAX($AF$1:$AF10)) | AL10: =IF(AND(AC10=5,AG10=TRUE),AB10,"") -> 中史 | AM10: =IF(AL10="","",MAX($AF$1:$AF10)) -> 1 | AO10: JS3120 | AP10: BEng (Hons) Scheme in Civil Engineering and Sustainable Development | AQ10: {=_xlfn.TEXTJOIN(", ",TRUE,_xlfn._xlws.FILTER($AH$1:$AH$1640,$AI$1:$AI$1640=ROW()-1,""))} -> BIO, CHEM, 中文, ECON, ENG, GEOG, MATH, M2, PHY | AR10: {=_xlfn.TEXTJOIN(", ",TRUE,_xlfn._xlws.FILTER($AJ$1:$AJ$1640,$AK$1:$AK$1640=ROW()-1,""))} -> ICT, 通 | AS10: {=_xlfn.TEXTJOIN(", ",TRUE,_xlfn._xlws.FILTER($AL$1:$AL$1640,$AM$1:$AM$1640=ROW()-1,""))} -> BAFS, 中史, HMSC, HIST, VA | AV10: ENG
A11: 中文 | C11: 7 | AB11: {=_xlfn._xlws.FILTER(A11:Z11,A11:Z11<>"","")} -> 中文 | AC11: 7 | AF11: {=IF(AD11="","",SUMPRODUCT(IF(LEFT($AD$1:AD11,2)="JS",1,0)))} | AG11: =IF(ISNUMBER(MATCH(AB11,$AV$3:$AV$18,0)),TRUE,"") -> TRUE | AH11: =IF(AND(AC11=10,AG11=TRUE),AB11,"") | AI11: =IF(AH11="","",MAX($AF$1:$AF11)) | AJ11: =IF(AND(AC11=7,AG11=TRUE),AB11,"") -> 中文 | AK11: =IF(AJ11="","",MAX($AF$1:$AF11)) -> 1 | AL11: =IF(AND(AC11=5,AG11=TRUE),AB11,"") | AM11: =IF(AL11="","",MAX($AF$1:$AF11)) | AO11: JS3130 | AP11: BSc (Hons) Scheme in Spatial Data Science and Smart Cities | AQ11: {=_xlfn.TEXTJOIN(", ",TRUE,_xlfn._xlws.FILTER($AH$1:$AH$1640,$AI$1:$AI$1640=ROW()-1,""))} -> ENG, GEOG, ICT, MATH, M2, PHY | AR11: {=_xlfn.TEXTJOIN(", ",TRUE,_xlfn._xlws.FILTER($AJ$1:$AJ$1640,$AK$1:$AK$1640=ROW()-1,""))} -> BIO, BAFS, CHEM, 中史, 中文, ECON, HMSC, HIST, 通, VA | AS11: {=_xlfn.TEXTJOIN(", ",TRUE,_xlfn._xlws.FILTER($AL$1:$AL$1640,$AM$1:$AM$1640=ROW()-1,""))} | AV11: GEOG
A12: Chinese Literature | C12: 5 | AB12: {=_xlfn._xlws.FILTER(A12:Z12,A12:Z12<>"","")} -> Chinese Literature | AC12: 5 | AF12: {=IF(AD12="","",SUMPRODUCT(IF(LEFT($AD$1:AD12,2)="JS",1,0)))} | AG12: =IF(ISNUMBER(MATCH(AB12,$AV$3:$AV$18,0)),TRUE,"") | AH12: =IF(AND(AC12=10,AG12=TRUE),AB12,"") | AI12: =IF(AH12="","",MAX($AF$1:$AF12)) | AJ12: =IF(AND(AC12=7,AG12=TRUE),AB12,"") | AK12: =IF(AJ12="","",MAX($AF$1:$AF12)) | AL12: =IF(AND(AC12=5,AG12=TRUE),AB12,"") | AM12: =IF(AL12="","",MAX($AF$1:$AF12)) | AO12: JS3140 | AP12: BEng (Hons) Scheme in Aviation Engineering | AQ12: {=_xlfn.TEXTJOIN(", ",TRUE,_xlfn._xlws.FILTER($AH$1:$AH$1640,$AI$1:$AI$1640=ROW()-1,""))} -> CHEM, ENG, ICT, MATH, M2, PHY | AR12: {=_xlfn.TEXTJOIN(", ",TRUE,_xlfn._xlws.FILTER($AJ$1:$AJ$1640,$AK$1:$AK$1640=ROW()-1,""))} -> BIO, 中文, 通 | AS12: {=_xlfn.TEXTJOIN(", ",TRUE,_xlfn._xlws.FILTER($AL$1:$AL$1640,$AM$1:$AM$1640=ROW()-1,""))} -> BAFS, 中史, ECON, GEOG, HMSC, HIST, VA | AV12: HMSC
A13: Combined Science: Biology + Chemistry | C13: 10 | AB13: {=_xlfn._xlws.FILTER(A13:Z13,A13:Z13<>"","")} -> Combined Science: Biology + Chemistry | AC13: 10 | AF13: {=IF(AD13="","",SUMPRODUCT(IF(LEFT($AD$1:AD13,2)="JS",1,0)))} | AG13: =IF(ISNUMBER(MATCH(AB13,$AV$3:$AV$18,0)),TRUE,"") | AH13: =IF(AND(AC13=10,AG13=TRUE),AB13,"") | AI13: =IF(AH13="","",MAX($AF$1:$AF13)) | AJ13: =IF(AND(AC13=7,AG13=TRUE),AB13,"") | AK13: =IF(AJ13="","",MAX($AF$1:$AF13)) | AL13: =IF(AND(AC13=5,AG13=TRUE),AB13,"") | AM13: =IF(AL13="","",MAX($AF$1:$AF13)) | AO13: JS3150 | AP13: BSc (Hons) Scheme in Biomedical Engineering | AQ13: {=_xlfn.TEXTJOIN(", ",TRUE,_xlfn._xlws.FILTER($AH$1:$AH$1640,$AI$1:$AI$1640=ROW()-1,""))} -> BIO, CHEM, MATH, M2, PHY | AR13: {=_xlfn.TEXTJOIN(", ",TRUE,_xlfn._xlws.FILTER($AJ$1:$AJ$1640,$AK$1:$AK$1640=ROW()-1,""))} -> 中文, ENG, 通 | AS13: {=_xlfn.TEXTJOIN(", ",TRUE,_xlfn._xlws.FILTER($AL$1:$AL$1640,$AM$1:$AM$1640=ROW()-1,""))} -> BAFS, 中史, ECON, GEOG, HMSC, HIST, ICT, VA | AV13: HIST
A14: Combined Science: Biology + Physics | C14: 10 | AB14: {=_xlfn._xlws.FILTER(A14:Z14,A14:Z14<>"","")} -> Combined Science: Biology + Physics | AC14: 10 | AF14: {=IF(AD14="","",SUMPRODUCT(IF(LEFT($AD$1:AD14,2)="JS",1,0)))} | AG14: =IF(ISNUMBER(MATCH(AB14,$AV$3:$AV$18,0)),TRUE,"") | AH14: =IF(AND(AC14=10,AG14=TRUE),AB14,"") | AI14: =IF(AH14="","",MAX($AF$1:$AF14)) | AJ14: =IF(AND(AC14=7,AG14=TRUE),AB14,"") | AK14: =IF(AJ14="","",MAX($AF$1:$AF14)) | AL14: =IF(AND(AC14=5,AG14=TRUE),AB14,"") | AM14: =IF(AL14="","",MAX($AF$1:$AF14)) | AO14: JS3170 | AP14: BEng (Hons) Scheme in Electrical Engineering | AQ14: {=_xlfn.TEXTJOIN(", ",TRUE,_xlfn._xlws.FILTER($AH$1:$AH$1640,$AI$1:$AI$1640=ROW()-1,""))} -> BIO, CHEM, ENG, ICT, MATH, M2, PHY | AR14: {=_xlfn.TEXTJOIN(", ",TRUE,_xlfn._xlws.FILTER($AJ$1:$AJ$1640,$AK$1:$AK$1640=ROW()-1,""))} -> BAFS, 中文, ECON, 通 | AS14: {=_xlfn.TEXTJOIN(", ",TRUE,_xlfn._xlws.FILTER($AL$1:$AL$1640,$AM$1:$AM$1640=ROW()-1,""))} -> 中史, GEOG, HMSC, HIST, VA | AV14: ICT
A15: Combined Science: Physics + Chemistry | C15: 10 | AB15: {=_xlfn._xlws.FILTER(A15:Z15,A15:Z15<>"","")} -> Combined Science: Physics + Chemistry | AC15: 10 | AF15: {=IF(AD15="","",SUMPRODUCT(IF(LEFT($AD$1:AD15,2)="JS",1,0)))} | AG15: =IF(ISNUMBER(MATCH(AB15,$AV$3:$AV$18,0)),TRUE,"") | AH15: =IF(AND(AC15=10,AG15=TRUE),AB15,"") | AI15: =IF(AH15="","",MAX($AF$1:$AF15)) | AJ15: =IF(AND(AC15=7,AG15=TRUE),AB15,"") | AK15: =IF(AJ15="","",MAX($AF$1:$AF15)) | AL15: =IF(AND(AC15=5,AG15=TRUE),AB15,"") | AM15: =IF(AL15="","",MAX($AF$1:$AF15)) | AO15: JS3180 | AP15: BEng (Hons) / BSc (Hons) Scheme in Information and Artificial Intelligence Engineering | AQ15: {=_xlfn.TEXTJOIN(", ",TRUE,_xlfn._xlws.FILTER($AH$1:$AH$1640,$AI$1:$AI$1640=ROW()-1,""))} -> BIO, CHEM, ENG, ICT, MATH, M2, PHY | AR15: {=_xlfn.TEXTJOIN(", ",TRUE,_xlfn._xlws.FILTER($AJ$1:$AJ$1640,$AK$1:$AK$1640=ROW()-1,""))} -> 中文, 通 | AS15: {=_xlfn.TEXTJOIN(", ",TRUE,_xlfn._xlws.FILTER($AL$1:$AL$1640,$AM$1:$AM$1640=ROW()-1,""))} -> BAFS, 中史, ECON, GEOG, HMSC, HIST, VA | AV15: MATH
A16: Design and Applied Technology | C16: 5 | AB16: {=_xlfn._xlws.FILTER(A16:Z16,A16:Z16<>"","")} -> Design and Applied Technology | AC16: 5 | AF16: {=IF(AD16="","",SUMPRODUCT(IF(LEFT($AD$1:AD16,2)="JS",1,0)))} | AG16: =IF(ISNUMBER(MATCH(AB16,$AV$3:$AV$18,0)),TRUE,"") | AH16: =IF(AND(AC16=10,AG16=TRUE),AB16,"") | AI16: =IF(AH16="","",MAX($AF$1:$AF16)) | AJ16: =IF(AND(AC16=7,AG16=TRUE),AB16,"") | AK16: =IF(AJ16="","",MAX($AF$1:$AF16)) | AL16: =IF(AND(AC16=5,AG16=TRUE),AB16,"") | AM16: =IF(AL16="","",MAX($AF$1:$AF16)) | AO16: JS3240 | AP16: BA (Hons) Scheme in English and Applied Linguistics | AQ16: {=_xlfn.TEXTJOIN(", ",TRUE,_xlfn._xlws.FILTER($AH$1:$AH$1640,$AI$1:$AI$1640=ROW()-1,""))} -> 中文, ENG | AR16: {=_xlfn.TEXTJOIN(", ",TRUE,_xlfn._xlws.FILTER($AJ$1:$AJ$1640,$AK$1:$AK$1640=ROW()-1,""))} -> BAFS, 中史, GEOG, HMSC, HIST, ICT, 通, MATH, VA | AS16: {=_xlfn.TEXTJOIN(", ",TRUE,_xlfn._xlws.FILTER($AL$1:$AL$1640,$AM$1:$AM$1640=ROW()-1,""))} -> BIO, CHEM, ECON, M2, PHY | AV16: M2
... A18: ENG | C18: 10 | AB18: {=_xlfn._xlws.FILTER(A18:Z18,A18:Z18<>"","")} -> ENG | AC18: 10 | AF18: {=IF(AD18="","",SUMPRODUCT(IF(LEFT($AD$1:AD18,2)="JS",1,0)))} | AG18: =IF(ISNUMBER(MATCH(AB18,$AV$3:$AV$18,0)),TRUE,"") -> TRUE | AH18: =IF(AND(AC18=10,AG18=TRUE),AB18,"") -> ENG | AI18: =IF(AH18="","",MAX($AF$1:$AF18)) -> 1 | AJ18: =IF(AND(AC18=7,AG18=TRUE),AB18,"") | AK18: =IF(AJ18="","",MAX($AF$1:$AF18)) | AL18: =IF(AND(AC18=5,AG18=TRUE),AB18,"") | AM18: =IF(AL18="","",MAX($AF$1:$AF18)) | AO18: JS3290 | AP18: BSc (Hons) Scheme in Optometry | AQ18: {=_xlfn.TEXTJOIN(", ",TRUE,_xlfn._xlws.FILTER($AH$1:$AH$1640,$AI$1:$AI$1640=ROW()-1,""))} -> BIO, CHEM, ENG, MATH, M2, PHY | AR18: {=_xlfn.TEXTJOIN(", ",TRUE,_xlfn._xlws.FILTER($AJ$1:$AJ$1640,$AK$1:$AK$1640=ROW()-1,""))} -> 中文, 通 | AS18: {=_xlfn.TEXTJOIN(", ",TRUE,_xlfn._xlws.FILTER($AL$1:$AL$1640,$AM$1:$AM$1640=ROW()-1,""))} -> BAFS, 中史, ECON, GEOG, HMSC, HIST, ICT, VA | AV18: VA
A19: Ethics and Religious Studies | C19: 5 | AB19: {=_xlfn._xlws.FILTER(A19:Z19,A19:Z19<>"","")} -> Ethics and Religious Studies | AC19: 5 | AF19: {=IF(AD19="","",SUMPRODUCT(IF(LEFT($AD$1:AD19,2)="JS",1,0)))} | AG19: =IF(ISNUMBER(MATCH(AB19,$AV$3:$AV$18,0)),TRUE,"") | AH19: =IF(AND(AC19=10,AG19=TRUE),AB19,"") | AI19: =IF(AH19="","",MAX($AF$1:$AF19)) | AJ19: =IF(AND(AC19=7,AG19=TRUE),AB19,"") | AK19: =IF(AJ19="","",MAX($AF$1:$AF19)) | AL19: =IF(AND(AC19=5,AG19=TRUE),AB19,"") | AM19: =IF(AL19="","",MAX($AF$1:$AF19)) | AO19: JS3310 | AP19: BSc (Hons) Scheme in Hotel and Tourism Management | AQ19: {=_xlfn.TEXTJOIN(", ",TRUE,_xlfn._xlws.FILTER($AH$1:$AH$1640,$AI$1:$AI$1640=ROW()-1,""))} -> ENG | AR19: {=_xlfn.TEXTJOIN(", ",TRUE,_xlfn._xlws.FILTER($AJ$1:$AJ$1640,$AK$1:$AK$1640=ROW()-1,""))} -> BIO, BAFS, CHEM, 中史, 中文, ECON, GEOG, HMSC, HIST, ICT, 通, MATH, M2, PHY, VA | AS19: {=_xlfn.TEXTJOIN(", ",TRUE,_xlfn._xlws.FILTER($AL$1:$AL$1640,$AM$1:$AM$1640=ROW()-1,""))}
A20: GEOG | C20: 5 | AB20: {=_xlfn._xlws.FILTER(A20:Z20,A20:Z20<>"","")} -> GEOG | AC20: 5 | AF20: {=IF(AD20="","",SUMPRODUCT(IF(LEFT($AD$1:AD20,2)="JS",1,0)))} | AG20: =IF(ISNUMBER(MATCH(AB20,$AV$3:$AV$18,0)),TRUE,"") -> TRUE | AH20: =IF(AND(AC20=10,AG20=TRUE),AB20,"") | AI20: =IF(AH20="","",MAX($AF$1:$AF20)) | AJ20: =IF(AND(AC20=7,AG20=TRUE),AB20,"") | AK20: =IF(AJ20="","",MAX($AF$1:$AF20)) | AL20: =IF(AND(AC20=5,AG20=TRUE),AB20,"") -> GEOG | AM20: =IF(AL20="","",MAX($AF$1:$AF20)) -> 1 | AO20: JS3320 | AP20: BA (Hons) Scheme in Chinese History and Culture | AQ20: {=_xlfn.TEXTJOIN(", ",TRUE,_xlfn._xlws.FILTER($AH$1:$AH$1640,$AI$1:$AI$1640=ROW()-1,""))} -> 中史, 中文, ENG, HIST | AR20: {=_xlfn.TEXTJOIN(", ",TRUE,_xlfn._xlws.FILTER($AJ$1:$AJ$1640,$AK$1:$AK$1640=ROW()-1,""))} -> 通, MATH | AS20: {=_xlfn.TEXTJOIN(", ",TRUE,_xlfn._xlws.FILTER($AL$1:$AL$1640,$AM$1:$AM$1640=ROW()-1,""))} -> BIO, BAFS, CHEM, ECON, GEOG, HMSC, ICT, M2, PHY, VA
A21: HMSC | C21: 5 | AB21: {=_xlfn._xlws.FILTER(A21:Z21,A21:Z21<>"","")} -> HMSC | AC21: 5 | AF21: {=IF(AD21="","",SUMPRODUCT(IF(LEFT($AD$1:AD21,2)="JS",1,0)))} | AG21: =IF(ISNUMBER(MATCH(AB21,$AV$3:$AV$18,0)),TRUE,"") -> TRUE | AH21: =IF(AND(AC21=10,AG21=TRUE),AB21,"") | AI21: =IF(AH21="","",MAX($AF$1:$AF21)) | AJ21: =IF(AND(AC21=7,AG21=TRUE),AB21,"") | AK21: =IF(AJ21="","",MAX($AF$1:$AF21)) | AL21: =IF(AND(AC21=5,AG21=TRUE),AB21,"") -> HMSC | AM21: =IF(AL21="","",MAX($AF$1:$AF21)) -> 1 | AO21: JS3330 | AP21: BA (Hons) / BSc (Hons) Scheme in Language Sciences, Translation, and Speech Therapy | AQ21: {=_xlfn.TEXTJOIN(", ",TRUE,_xlfn._xlws.FILTER($AH$1:$AH$1640,$AI$1:$AI$1640=ROW()-1,""))} -> 中文, ENG, MATH | AR21: {=_xlfn.TEXTJOIN(", ",TRUE,_xlfn._xlws.FILTER($AJ$1:$AJ$1640,$AK$1:$AK$1640=ROW()-1,""))} -> BIO, BAFS, CHEM, 中史, ECON, GEOG, HMSC, HIST, ICT, 通, M2, PHY | AS21: {=_xlfn.TEXTJOIN(", ",TRUE,_xlfn._xlws.FILTER($AL$1:$AL$1640,$AM$1:$AM$1640=ROW()-1,""))} -> VA
A22: HIST | C22: 5 | AB22: {=_xlfn._xlws.FILTER(A22:Z22,A22:Z22<>"","")} -> HIST | AC22: 5 | AF22: {=IF(AD22="","",SUMPRODUCT(IF(LEFT($AD$1:AD22,2)="JS",1,0)))} | AG22: =IF(ISNUMBER(MATCH(AB22,$AV$3:$AV$18,0)),TRUE,"") -> TRUE | AH22: =IF(AND(AC22=10,AG22=TRUE),AB22,"") | AI22: =IF(AH22="","",MAX($AF$1:$AF22)) | AJ22: =IF(AND(AC22=7,AG22=TRUE),AB22,"") | AK22: =IF(AJ22="","",MAX($AF$1:$AF22)) | AL22: =IF(AND(AC22=5,AG22=TRUE),AB22,"") -> HIST | AM22: =IF(AL22="","",MAX($AF$1:$AF22)) -> 1 | AO22: JS3337 | AP22: BSc (Hons) Scheme in Nursing - Mental Health Nursing | AQ22: {=_xlfn.TEXTJOIN(", ",TRUE,_xlfn._xlws.FILTER($AH$1:$AH$1640,$AI$1:$AI$1640=ROW()-1,""))} -> BIO, 中文, ENG, 通, MATH | AR22: {=_xlfn.TEXTJOIN(", ",TRUE,_xlfn._xlws.FILTER($AJ$1:$AJ$1640,$AK$1:$AK$1640=ROW()-1,""))} -> BAFS, CHEM, 中史, ECON, GEOG, HMSC, HIST, ICT, M2, PHY, VA | AS22: {=_xlfn.TEXTJOIN(", ",TRUE,_xlfn._xlws.FILTER($AL$1:$AL$1640,$AM$1:$AM$1640=ROW()-1,""))}
A23: ICT | C23: 5 | AB23: {=_xlfn._xlws.FILTER(A23:Z23,A23:Z23<>"","")} -> ICT | AC23: 5 | AF23: {=IF(AD23="","",SUMPRODUCT(IF(LEFT($AD$1:AD23,2)="JS",1,0)))} | AG23: =IF(ISNUMBER(MATCH(AB23,$AV$3:$AV$18,0)),TRUE,"") -> TRUE | AH23: =IF(AND(AC23=10,AG23=TRUE),AB23,"") | AI23: =IF(AH23="","",MAX($AF$1:$AF23)) | AJ23: =IF(AND(AC23=7,AG23=TRUE),AB23,"") | AK23: =IF(AJ23="","",MAX($AF$1:$AF23)) | AL23: =IF(AND(AC23=5,AG23=TRUE),AB23,"") -> ICT | AM23: =IF(AL23="","",MAX($AF$1:$AF23)) -> 1 | AO23: JS3478 | AP23: BSc (Hons) Scheme in Medical Laboratory Science and Radiography - Medical Laboratory Science | AQ23: {=_xlfn.TEXTJOIN(", ",TRUE,_xlfn._xlws.FILTER($AH$1:$AH$1640,$AI$1:$AI$1640=ROW()-1,""))} -> BIO, CHEM, 中文, ENG, MATH, M2 | AR23: {=_xlfn.TEXTJOIN(", ",TRUE,_xlfn._xlws.FILTER($AJ$1:$AJ$1640,$AK$1:$AK$1640=ROW()-1,""))} -> 通, PHY | AS23: {=_xlfn.TEXTJOIN(", ",TRUE,_xlfn._xlws.FILTER($AL$1:$AL$1640,$AM$1:$AM$1640=ROW()-1,""))} -> BAFS, 中史, ECON, GEOG, HMSC, HIST, ICT, VA
A24: Integrated Science | C24: 7 | AB24: {=_xlfn._xlws.FILTER(A24:Z24,A24:Z24<>"","")} -> Integrated Science | AC24: 7 | AF24: {=IF(AD24="","",SUMPRODUCT(IF(LEFT($AD$1:AD24,2)="JS",1,0)))} | AG24: =IF(ISNUMBER(MATCH(AB24,$AV$3:$AV$18,0)),TRUE,"") | AH24: =IF(AND(AC24=10,AG24=TRUE),AB24,"") | AI24: =IF(AH24="","",MAX($AF$1:$AF24)) | AJ24: =IF(AND(AC24=7,AG24=TRUE),AB24,"") | AK24: =IF(AJ24="","",MAX($AF$1:$AF24)) | AL24: =IF(AND(AC24=5,AG24=TRUE),AB24,"") | AM24: =IF(AL24="","",MAX($AF$1:$AF24)) | AO24: JS3557 | AP24: BEng (Hons) Scheme in Product and Industrial Engineering | AQ24: {=_xlfn.TEXTJOIN(", ",TRUE,_xlfn._xlws.FILTER($AH$1:$AH$1640,$AI$1:$AI$1640=ROW()-1,""))} -> ENG, MATH | AR24: {=_xlfn.TEXTJOIN(", ",TRUE,_xlfn._xlws.FILTER($AJ$1:$AJ$1640,$AK$1:$AK$1640=ROW()-1,""))} -> 中文, 通 | AS24: {=_xlfn.TEXTJOIN(", ",TRUE,_xlfn._xlws.FILTER($AL$1:$AL$1640,$AM$1:$AM$1640=ROW()-1,""))} -> BIO, BAFS, CHEM, 中史, ECON, GEOG, HMSC, HIST, ICT, M2, PHY, VA
A25: 通 | C25: 7 | AB25: {=_xlfn._xlws.FILTER(A25:Z25,A25:Z25<>"","")} -> 通 | AC25: 7 | AF25: {=IF(AD25="","",SUMPRODUCT(IF(LEFT($AD$1:AD25,2)="JS",1,0)))} | AG25: =IF(ISNUMBER(MATCH(AB25,$AV$3:$AV$18,0)),TRUE,"") -> TRUE | AH25: =IF(AND(AC25=10,AG25=TRUE),AB25,"") | AI25: =IF(AH25="","",MAX($AF$1:$AF25)) | AJ25: =IF(AND(AC25=7,AG25=TRUE),AB25,"") -> 通 | AK25: =IF(AJ25="","",MAX($AF$1:$AF25)) -> 1 | AL25: =IF(AND(AC25=5,AG25=TRUE),AB25,"") | AM25: =IF(AL25="","",MAX($AF$1:$AF25)) | AO25: JS3569 | AP25: BA (Hons) Scheme in Design | AQ25: {=_xlfn.TEXTJOIN(", ",TRUE,_xlfn._xlws.FILTER($AH$1:$AH$1640,$AI$1:$AI$1640=ROW()-1,""))} -> 中文, ENG, ICT, 通, MATH, VA | AR25: {=_xlfn.TEXTJOIN(", ",TRUE,_xlfn._xlws.FILTER($AJ$1:$AJ$1640,$AK$1:$AK$1640=ROW()-1,""))} -> BAFS, ECON, HIST | AS25: {=_xlfn.TEXTJOIN(", ",TRUE,_xlfn._xlws.FILTER($AL$1:$AL$1640,$AM$1:$AM$1640=ROW()-1,""))} -> BIO, CHEM, 中史, GEOG, HMSC, M2, PHY
A26: Literature in English | C26: 5 | AB26: {=_xlfn._xlws.FILTER(A26:Z26,A26:Z26<>"","")} -> Literature in English | AC26: 5 | AF26: {=IF(AD26="","",SUMPRODUCT(IF(LEFT($AD$1:AD26,2)="JS",1,0)))} | AG26: =IF(ISNUMBER(MATCH(AB26,$AV$3:$AV$18,0)),TRUE,"") | AH26: =IF(AND(AC26=10,AG26=TRUE),AB26,"") | AI26: =IF(AH26="","",MAX($AF$1:$AF26)) | AJ26: =IF(AND(AC26=7,AG26=TRUE),AB26,"") | AK26: =IF(AJ26="","",MAX($AF$1:$AF26)) | AL26: =IF(AND(AC26=5,AG26=TRUE),AB26,"") | AM26: =IF(AL26="","",MAX($AF$1:$AF26)) | AO26: JS3571 | AP26: BSc (Hons) Scheme in Logistics and Enterprise Engineering | AQ26: {=_xlfn.TEXTJOIN(", ",TRUE,_xlfn._xlws.FILTER($AH$1:$AH$1640,$AI$1:$AI$1640=ROW()-1,""))} -> ENG, MATH | AR26: {=_xlfn.TEXTJOIN(", ",TRUE,_xlfn._xlws.FILTER($AJ$1:$AJ$1640,$AK$1:$AK$1640=ROW()-1,""))} -> 中文, 通 | AS26: {=_xlfn.TEXTJOIN(", ",TRUE,_xlfn._xlws.FILTER($AL$1:$AL$1640,$AM$1:$AM$1640=ROW()-1,""))} -> BIO, BAFS, CHEM, 中史, ECON, GEOG, HMSC, HIST, ICT, M2, PHY, VA
A27: MATH | C27: 10 | AB27: {=_xlfn._xlws.FILTER(A27:Z27,A27:Z27<>"","")} -> MATH | AC27: 10 | AF27: {=IF(AD27="","",SUMPRODUCT(IF(LEFT($AD$1:AD27,2)="JS",1,0)))} | AG27: =IF(ISNUMBER(MATCH(AB27,$AV$3:$AV$18,0)),TRUE,"") -> TRUE | AH27: =IF(AND(AC27=10,AG27=TRUE),AB27,"") -> MATH | AI27: =IF(AH27="","",MAX($AF$1:$AF27)) -> 1 | AJ27: =IF(AND(AC27=7,AG27=TRUE),AB27,"") | AK27: =IF(AJ27="","",MAX($AF$1:$AF27)) | AL27: =IF(AND(AC27=5,AG27=TRUE),AB27,"") | AM27: =IF(AL27="","",MAX($AF$1:$AF27)) | AO27: JS3612 | AP27: BSc (Hons) Scheme in Medical Laboratory Science and Radiography - Radiography | AQ27: {=_xlfn.TEXTJOIN(", ",TRUE,_xlfn._xlws.FILTER($AH$1:$AH$1640,$AI$1:$AI$1640=ROW()-1,""))} -> BIO, CHEM, 中文, ENG, MATH, PHY | AR27: {=_xlfn.TEXTJOIN(", ",TRUE,_xlfn._xlws.FILTER($AJ$1:$AJ$1640,$AK$1:$AK$1640=ROW()-1,""))} -> 通, M2 | AS27: {=_xlfn.TEXTJOIN(", ",TRUE,_xlfn._xlws.FILTER($AL$1:$AL$1640,$AM$1:$AM$1640=ROW()-1,""))} -> BAFS, 中史, ECON, GEOG, HMSC, HIST, ICT, VA
A28: M2 | C28: 7 | AB28: {=_xlfn._xlws.FILTER(A28:Z28,A28:Z28<>"","")} -> M2 | AC28: 7 | AF28: {=IF(AD28="","",SUMPRODUCT(IF(LEFT($AD$1:AD28,2)="JS",1,0)))} | AG28: =IF(ISNUMBER(MATCH(AB28,$AV$3:$AV$18,0)),TRUE,"") -> TRUE | AH28: =IF(AND(AC28=10,AG28=TRUE),AB28,"") | AI28: =IF(AH28="","",MAX($AF$1:$AF28)) | AJ28: =IF(AND(AC28=7,AG28=TRUE),AB28,"") -> M2 | AK28: =IF(AJ28="","",MAX($AF$1:$AF28)) -> 1 | AL28: =IF(AND(AC28=5,AG28=TRUE),AB28,"") | AM28: =IF(AL28="","",MAX($AF$1:$AF28)) | AO28: JS3624 | AP28: BSc (Hons) Scheme in Rehabilitation Sciences - Occupational Therapy | AQ28: {=_xlfn.TEXTJOIN(", ",TRUE,_xlfn._xlws.FILTER($AH$1:$AH$1640,$AI$1:$AI$1640=ROW()-1,""))} -> BIO, 中文, ENG, PHY | AR28: {=_xlfn.TEXTJOIN(", ",TRUE,_xlfn._xlws.FILTER($AJ$1:$AJ$1640,$AK$1:$AK$1640=ROW()-1,""))} -> CHEM, 中史, ECON, GEOG, HMSC, HIST, ICT, 通, MATH, M2 | AS28: {=_xlfn.TEXTJOIN(", ",TRUE,_xlfn._xlws.FILTER($AL$1:$AL$1640,$AM$1:$AM$1640=ROW()-1,""))} -> BAFS, VA
A29: Mathematics (Extended part - Calculus and Statistics) | C29: 7 | AB29: {=_xlfn._xlws.FILTER(A29:Z29,A29:Z29<>"","")} -> Mathematics (Extended part - Calculus and Statistics) | AC29: 7 | AF29: {=IF(AD29="","",SUMPRODUCT(IF(LEFT($AD$1:AD29,2)="JS",1,0)))} | AG29: =IF(ISNUMBER(MATCH(AB29,$AV$3:$AV$18,0)),TRUE,"") | AH29: =IF(AND(AC29=10,AG29=TRUE),AB29,"") | AI29: =IF(AH29="","",MAX($AF$1:$AF29)) | AJ29: =IF(AND(AC29=7,AG29=TRUE),AB29,"") | AK29: =IF(AJ29="","",MAX($AF$1:$AF29)) | AL29: =IF(AND(AC29=5,AG29=TRUE),AB29,"") | AM29: =IF(AL29="","",MAX($AF$1:$AF29)) | AO29: JS3636 | AP29: BSc (Hons) Scheme in Rehabilitation Sciences - Physiotherapy | AQ29: {=_xlfn.TEXTJOIN(", ",TRUE,_xlfn._xlws.FILTER($AH$1:$AH$1640,$AI$1:$AI$1640=ROW()-1,""))} -> BIO, 中文, ENG, PHY | AR29: {=_xlfn.TEXTJOIN(", ",TRUE,_xlfn._xlws.FILTER($AJ$1:$AJ$1640,$AK$1:$AK$1640=ROW()-1,""))} -> CHEM, HMSC, 通, MATH | AS29: {=_xlfn.TEXTJOIN(", ",TRUE,_xlfn._xlws.FILTER($AL$1:$AL$1640,$AM$1:$AM$1640=ROW()-1,""))} -> BAFS, 中史, ECON, GEOG, HIST, ICT, M2, VA
A30: Music | C30: 5 | AB30: {=_xlfn._xlws.FILTER(A30:Z30,A30:Z30<>"","")} -> Music | AC30: 5 | AF30: {=IF(AD30="","",SUMPRODUCT(IF(LEFT($AD$1:AD30,2)="JS",1,0)))} | AG30: =IF(ISNUMBER(MATCH(AB30,$AV$3:$AV$18,0)),TRUE,"") | AH30: =IF(AND(AC30=10,AG30=TRUE),AB30,"") | AI30: =IF(AH30="","",MAX($AF$1:$AF30)) | AJ30: =IF(AND(AC30=7,AG30=TRUE),AB30,"") | AK30: =IF(AJ30="","",MAX($AF$1:$AF30)) | AL30: =IF(AND(AC30=5,AG30=TRUE),AB30,"") | AM30: =IF(AL30="","",MAX($AF$1:$AF30)) | AO30: JS3648 | AP30: BSc (Hons) Scheme in Nursing - Nursing | AQ30: {=_xlfn.TEXTJOIN(", ",TRUE,_xlfn._xlws.FILTER($AH$1:$AH$1640,$AI$1:$AI$1640=ROW()-1,""))} -> BIO, 中文, ENG, 通, MATH | AR30: {=_xlfn.TEXTJOIN(", ",TRUE,_xlfn._xlws.FILTER($AJ$1:$AJ$1640,$AK$1:$AK$1640=ROW()-1,""))} -> BAFS, CHEM, 中史, ECON, GEOG, HMSC, HIST, ICT, M2, PHY, VA | AS30: {=_xlfn.TEXTJOIN(", ",TRUE,_xlfn._xlws.FILTER($AL$1:$AL$1640,$AM$1:$AM$1640=ROW()-1,""))}
... A32: PHY | C32: 7 | AB32: {=_xlfn._xlws.FILTER(A32:Z32,A32:Z32<>"","")} -> PHY | AC32: 7 | AF32: {=IF(AD32="","",SUMPRODUCT(IF(LEFT($AD$1:AD32,2)="JS",1,0)))} | AG32: =IF(ISNUMBER(MATCH(AB32,$AV$3:$AV$18,0)),TRUE,"") -> TRUE | AH32: =IF(AND(AC32=10,AG32=TRUE),AB32,"") | AI32: =IF(AH32="","",MAX($AF$1:$AF32)) | AJ32: =IF(AND(AC32=7,AG32=TRUE),AB32,"") -> PHY | AK32: =IF(AJ32="","",MAX($AF$1:$AF32)) -> 1 | AL32: =IF(AND(AC32=5,AG32=TRUE),AB32,"") | AM32: =IF(AL32="","",MAX($AF$1:$AF32)) | AO32: JS3868 | AP32: BSc (Hons) Scheme in Computing and AI | AQ32: {=_xlfn.TEXTJOIN(", ",TRUE,_xlfn._xlws.FILTER($AH$1:$AH$1640,$AI$1:$AI$1640=ROW()-1,""))} -> BIO, BAFS, CHEM, ECON, ENG, ICT, MATH, M2, PHY | AR32: {=_xlfn.TEXTJOIN(", ",TRUE,_xlfn._xlws.FILTER($AJ$1:$AJ$1640,$AK$1:$AK$1640=ROW()-1,""))} -> 中史, 中文, GEOG, HMSC, HIST, 通, VA | AS32: {=_xlfn.TEXTJOIN(", ",TRUE,_xlfn._xlws.FILTER($AL$1:$AL$1640,$AM$1:$AM$1640=ROW()-1,""))}
A33: Technology and Living (Fashion, Clothing and Textiles) | C33: 5 | AB33: {=_xlfn._xlws.FILTER(A33:Z33,A33:Z33<>"","")} -> Technology and Living (Fashion, Clothing and Textiles) | AC33: 5 | AF33: {=IF(AD33="","",SUMPRODUCT(IF(LEFT($AD$1:AD33,2)="JS",1,0)))} | AG33: =IF(ISNUMBER(MATCH(AB33,$AV$3:$AV$18,0)),TRUE,"") | AH33: =IF(AND(AC33=10,AG33=TRUE),AB33,"") | AI33: =IF(AH33="","",MAX($AF$1:$AF33)) | AJ33: =IF(AND(AC33=7,AG33=TRUE),AB33,"") | AK33: =IF(AJ33="","",MAX($AF$1:$AF33)) | AL33: =IF(AND(AC33=5,AG33=TRUE),AB33,"") | AM33: =IF(AL33="","",MAX($AF$1:$AF33)) | AQ33: {=_xlfn.TEXTJOIN(", ",TRUE,_xlfn._xlws.FILTER($AH$1:$AH$1640,$AI$1:$AI$1640=ROW()-1,""))} | AR33: {=_xlfn.TEXTJOIN(", ",TRUE,_xlfn._xlws.FILTER($AJ$1:$AJ$1640,$AK$1:$AK$1640=ROW()-1,""))} | AS33: {=_xlfn.TEXTJOIN(", ",TRUE,_xlfn._xlws.FILTER($AL$1:$AL$1640,$AM$1:$AM$1640=ROW()-1,""))}
A34: Technology and Living (Food Science and Technology) | C34: 5 | AB34: {=_xlfn._xlws.FILTER(A34:Z34,A34:Z34<>"","")} -> Technology and Living (Food Science and Technology) | AC34: 5 | AF34: {=IF(AD34="","",SUMPRODUCT(IF(LEFT($AD$1:AD34,2)="JS",1,0)))} | AG34: =IF(ISNUMBER(MATCH(AB34,$AV$3:$AV$18,0)),TRUE,"") | AH34: =IF(AND(AC34=10,AG34=TRUE),AB34,"") | AI34: =IF(AH34="","",MAX($AF$1:$AF34)) | AJ34: =IF(AND(AC34=7,AG34=TRUE),AB34,"") | AK34: =IF(AJ34="","",MAX($AF$1:$AF34)) | AL34: =IF(AND(AC34=5,AG34=TRUE),AB34,"") | AM34: =IF(AL34="","",MAX($AF$1:$AF34)) | AQ34: {=_xlfn.TEXTJOIN(", ",TRUE,_xlfn._xlws.FILTER($AH$1:$AH$1640,$AI$1:$AI$1640=ROW()-1,""))} | AR34: {=_xlfn.TEXTJOIN(", ",TRUE,_xlfn._xlws.FILTER($AJ$1:$AJ$1640,$AK$1:$AK$1640=ROW()-1,""))} | AS34: {=_xlfn.TEXTJOIN(", ",TRUE,_xlfn._xlws.FILTER($AL$1:$AL$1640,$AM$1:$AM$1640=ROW()-1,""))}
A35: Tourism and Hospitality Studies | C35: 5 | AB35: {=_xlfn._xlws.FILTER(A35:Z35,A35:Z35<>"","")} -> Tourism and Hospitality Studies | AC35: 5 | AF35: {=IF(AD35="","",SUMPRODUCT(IF(LEFT($AD$1:AD35,2)="JS",1,0)))} | AG35: =IF(ISNUMBER(MATCH(AB35,$AV$3:$AV$18,0)),TRUE,"") | AH35: =IF(AND(AC35=10,AG35=TRUE),AB35,"") | AI35: =IF(AH35="","",MAX($AF$1:$AF35)) | AJ35: =IF(AND(AC35=7,AG35=TRUE),AB35,"") | AK35: =IF(AJ35="","",MAX($AF$1:$AF35)) | AL35: =IF(AND(AC35=5,AG35=TRUE),AB35,"") | AM35: =IF(AL35="","",MAX($AF$1:$AF35))
A36: VA | C36: 5 | AB36: {=_xlfn._xlws.FILTER(A36:Z36,A36:Z36<>"","")} -> VA | AC36: 5 | AF36: {=IF(AD36="","",SUMPRODUCT(IF(LEFT($AD$1:AD36,2)="JS",1,0)))} | AG36: =IF(ISNUMBER(MATCH(AB36,$AV$3:$AV$18,0)),TRUE,"") -> TRUE | AH36: =IF(AND(AC36=10,AG36=TRUE),AB36,"") | AI36: =IF(AH36="","",MAX($AF$1:$AF36)) | AJ36: =IF(AND(AC36=7,AG36=TRUE),AB36,"") | AK36: =IF(AJ36="","",MAX($AF$1:$AF36)) | AL36: =IF(AND(AC36=5,AG36=TRUE),AB36,"") -> VA | AM36: =IF(AL36="","",MAX($AF$1:$AF36)) -> 1
A37: Category B: Applied Learning Subjects | AB37: {=_xlfn._xlws.FILTER(A37:Z37,A37:Z37<>"","")} -> Category B: Applied Learning Subjects | AF37: {=IF(AD37="","",SUMPRODUCT(IF(LEFT($AD$1:AD37,2)="JS",1,0)))} | AG37: =IF(ISNUMBER(MATCH(AB37,$AV$3:$AV$18,0)),TRUE,"") | AH37: =IF(AND(AC37=10,AG37=TRUE),AB37,"") | AI37: =IF(AH37="","",MAX($AF$1:$AF37)) | AJ37: =IF(AND(AC37=7,AG37=TRUE),AB37,"") | AK37: =IF(AJ37="","",MAX($AF$1:$AF37)) | AL37: =IF(AND(AC37=5,AG37=TRUE),AB37,"") | AM37: =IF(AL37="","",MAX($AF$1:$AF37))
A38: Subject Name | C38: Subject Weighting for 2023/24 Admission Exercise * | AB38: {=_xlfn._xlws.FILTER(A38:Z38,A38:Z38<>"","")} -> Subject Name | AC38: Subject Weighting for 2023/24 Admission Exercise * | AF38: {=IF(AD38="","",SUMPRODUCT(IF(LEFT($AD$1:AD38,2)="JS",1,0)))} | AG38: =IF(ISNUMBER(MATCH(AB38,$AV$3:$AV$18,0)),TRUE,"") | AH38: =IF(AND(AC38=10,AG38=TRUE),AB38,"") | AI38: =IF(AH38="","",MAX($AF$1:$AF38)) | AJ38: =IF(AND(AC38=7,AG38=TRUE),AB38,"") | AK38: =IF(AJ38="","",MAX($AF$1:$AF38)) | AL38: =IF(AND(AC38=5,AG38=TRUE),AB38,"") | AM38: =IF(AL38="","",MAX($AF$1:$AF38))
A39: Child Care and Development | C39: 5 | AB39: {=_xlfn._xlws.FILTER(A39:Z39,A39:Z39<>"","")} -> Child Care and Development | AC39: 5 | AF39: {=IF(AD39="","",SUMPRODUCT(IF(LEFT($AD$1:AD39,2)="JS",1,0)))} | AG39: =IF(ISNUMBER(MATCH(AB39,$AV$3:$AV$18,0)),TRUE,"") | AH39: =IF(AND(AC39=10,AG39=TRUE),AB39,"") | AI39: =IF(AH39="","",MAX($AF$1:$AF39)) | AJ39: =IF(AND(AC39=7,AG39=TRUE),AB39,"") | AK39: =IF(AJ39="","",MAX($AF$1:$AF39)) | AL39: =IF(AND(AC39=5,AG39=TRUE),AB39,"") | AM39: =IF(AL39="","",MAX($AF$1:$AF39))
A40: Child Development and Care | C40: 5 | AB40: {=_xlfn._xlws.FILTER(A40:Z40,A40:Z40<>"","")} -> Child Development and Care | AC40: 5 | AF40: {=IF(AD40="","",SUMPRODUCT(IF(LEFT($AD$1:AD40,2)="JS",1,0)))} | AG40: =IF(ISNUMBER(MATCH(AB40,$AV$3:$AV$18,0)),TRUE,"") | AH40: =IF(AND(AC40=10,AG40=TRUE),AB40,"") | AI40: =IF(AH40="","",MAX($AF$1:$AF40)) | AJ40: =IF(AND(AC40=7,AG40=TRUE),AB40,"") | AK40: =IF(AJ40="","",MAX($AF$1:$AF40)) | AL40: =IF(AND(AC40=5,AG40=TRUE),AB40,"") | AM40: =IF(AL40="","",MAX($AF$1:$AF40))
A41: Environmental Engineering | C41: 5 | AB41: {=_xlfn._xlws.FILTER(A41:Z41,A41:Z41<>"","")} -> Environmental Engineering | AC41: 5 | AF41: {=IF(AD41="","",SUMPRODUCT(IF(LEFT($AD$1:AD41,2)="JS",1,0)))} | AG41: =IF(ISNUMBER(MATCH(AB41,$AV$3:$AV$18,0)),TRUE,"") | AH41: =IF(AND(AC41=10,AG41=TRUE),AB41,"") | AI41: =IF(AH41="","",MAX($AF$1:$AF41)) | AJ41: =IF(AND(AC41=7,AG41=TRUE),AB41,"") | AK41: =IF(AJ41="","",MAX($AF$1:$AF41)) | AL41: =IF(AND(AC41=5,AG41=TRUE),AB41,"") | AM41: =IF(AL41="","",MAX($AF$1:$AF41))
A42: Events Planning and Operation | C42: 5 | AB42: {=_xlfn._xlws.FILTER(A42:Z42,A42:Z42<>"","")} -> Events Planning and Operation | AC42: 5 | AF42: {=IF(AD42="","",SUMPRODUCT(IF(LEFT($AD$1:AD42,2)="JS",1,0)))} | AG42: =IF(ISNUMBER(MATCH(AB42,$AV$3:$AV$18,0)),TRUE,"") | AH42: =IF(AND(AC42=10,AG42=TRUE),AB42,"") | AI42: =IF(AH42="","",MAX($AF$1:$AF42)) | AJ42: =IF(AND(AC42=7,AG42=TRUE),AB42,"") | AK42: =IF(AJ42="","",MAX($AF$1:$AF42)) | AL42: =IF(AND(AC42=5,AG42=TRUE),AB42,"") | AM42: =IF(AL42="","",MAX($AF$1:$AF42))
...

Sheet 工作表1
A1: ='Table 1'!AO2 -> JS3010 | B1: =IF('Table 1'!AS2="","比重10:"&'Table 1'!AQ2&CHAR(10)&"比重7:其他","比重10:"&'Table 1'!AQ2&CHAR(10)&"比重7:"&'Table 1'!AR2&CHAR(10)&"比重5:"&"其他") -> 比重10:BIO, CHEM, ENG, MATH 比重7:中文, 通, M2, PHY 比重5:其他 | C1: 比重10:BIO, CHEM, ENG, MATH 比重7:中文, 通, M2, PHY 比重5:其他
A2: ='Table 1'!AO3 -> JS3020 | B2: =IF('Table 1'!AS3="","比重10:"&'Table 1'!AQ3&CHAR(10)&"比重7:其他","比重10:"&'Table 1'!AQ3&CHAR(10)&"比重7:"&'Table 1'!AR3&CHAR(10)&"比重5:"&"其他") -> 比重10:ENG, MATH 比重7:BIO, BAFS, CHEM, 中文, ECON, ICT, 通, M2, PHY 比重5:其他 | C2: 比重10:ENG, MATH 比重7:BIO, BAFS, CHEM, 中文, ECON, ICT, 通, M2, PHY 比重5:其他
A3: ='Table 1'!AO4 -> JS3050 | B3: =IF('Table 1'!AS4="","比重10:"&'Table 1'!AQ4&CHAR(10)&"比重7:其他","比重10:"&'Table 1'!AQ4&CHAR(10)&"比重7:"&'Table 1'!AR4&CHAR(10)&"比重5:"&"其他") -> 比重10:ECON, VA 比重7:中文, ENG, 通, MATH, M2 比重5:其他 | C3: 比重10:ECON, VA 比重7:中文, ENG, 通, MATH, M2 比重5:其他
A4: ='Table 1'!AO5 -> JS3060 | B4: =IF('Table 1'!AS5="","比重10:"&'Table 1'!AQ5&CHAR(10)&"比重7:其他","比重10:"&'Table 1'!AQ5&CHAR(10)&"比重7:"&'Table 1'!AR5&CHAR(10)&"比重5:"&"其他") -> 比重10:ENG, MATH 比重7:BIO, BAFS, CHEM, 中史, 中文, ECON, GEOG, HIST, 通, M2, PHY 比重5:其他 | C4: 比重10:ENG, MATH 比重7:BIO, BAFS, CHEM, 中史, 中文, ECON, GEOG, HIST, 通, M2, PHY 比重5:其他
A5: ='Table 1'!AO6 -> JS3070 | B5: =IF('Table 1'!AS6="","比重10:"&'Table 1'!AQ6&CHAR(10)&"比重7:其他","比重10:"&'Table 1'!AQ6&CHAR(10)&"比重7:"&'Table 1'!AR6&CHAR(10)&"比重5:"&"其他") -> 比重10:ENG, MATH 比重7:BIO, BAFS, CHEM, 中史, 中文, ECON, GEOG, HIST, 通, M2, PHY 比重5:其他 | C5: 比重10:ENG, MATH 比重7:BIO, BAFS, CHEM, 中史, 中文, ECON, GEOG, HIST, 通, M2, PHY 比重5:其他
A6: ='Table 1'!AO7 -> JS3080 | B6: =IF('Table 1'!AS7="","比重10:"&'Table 1'!AQ7&CHAR(10)&"比重7:其他","比重10:"&'Table 1'!AQ7&CHAR(10)&"比重7:"&'Table 1'!AR7&CHAR(10)&"比重5:"&"其他") -> 比重10:ENG, MATH 比重7:BIO, BAFS, CHEM, 中史, 中文, ECON, GEOG, HIST, 通, M2, PHY 比重5:其他 | C6: 比重10:ENG, MATH 比重7:BIO, BAFS, CHEM, 中史, 中文, ECON, GEOG, HIST, 通, M2, PHY 比重5:其他
A7: ='Table 1'!AO8 -> JS3100 | B7: =IF('Table 1'!AS8="","比重10:"&'Table 1'!AQ8&CHAR(10)&"比重7:其他","比重10:"&'Table 1'!AQ8&CHAR(10)&"比重7:"&'Table 1'!AR8&CHAR(10)&"比重5:"&"其他") -> 比重10:ENG 比重7:BIO, BAFS, CHEM, 中史, 中文, ECON, GEOG, HMSC, HIST, ICT, 通, MATH, M2, PHY 比重5:其他 | C7: 比重10:ENG 比重7:BIO, BAFS, CHEM, 中史, 中文, ECON, GEOG, HMSC, HIST, ICT, 通, MATH, M2, PHY 比重5:其他
A8: ='Table 1'!AO9 -> JS3110 | B8: =IF('Table 1'!AS9="","比重10:"&'Table 1'!AQ9&CHAR(10)&"比重7:其他","比重10:"&'Table 1'!AQ9&CHAR(10)&"比重7:"&'Table 1'!AR9&CHAR(10)&"比重5:"&"其他") -> 比重10:ENG, MATH, PHY 比重7:BIO, BAFS, CHEM, 中文, ECON, GEOG, HMSC, ICT, 通, M2 比重5:其他 | C8: 比重10:ENG, MATH, PHY 比重7:BIO, BAFS, CHEM, 中文, ECON, GEOG, HMSC, ICT, 通, M2 比重5:其他
A9: ='Table 1'!AO10 -> JS3120 | B9: =IF('Table 1'!AS10="","比重10:"&'Table 1'!AQ10&CHAR(10)&"比重7:其他","比重10:"&'Table 1'!AQ10&CHAR(10)&"比重7:"&'Table 1'!AR10&CHAR(10)&"比重5:"&"其他") -> 比重10:BIO, CHEM, 中文, ECON, ENG, GEOG, MATH, M2, PHY 比重7:ICT, 通 比重5:其他 | C9: 比重10:BIO, CHEM, 中文, ECON, ENG, GEOG, MATH, M2, PHY 比重7:ICT, 通 比重5:其他
A10: ='Table 1'!AO11 -> JS3130 | B10: =IF('Table 1'!AS11="","比重10:"&'Table 1'!AQ11&CHAR(10)&"比重7:其他","比重10:"&'Table 1'!AQ11&CHAR(10)&"比重7:"&'Table 1'!AR11&CHAR(10)&"比重5:"&"其他") -> 比重10:ENG, GEOG, ICT, MATH, M2, PHY 比重7:其他 | C10: 比重10:ENG, GEOG, ICT, MATH, M2, PHY 比重7:其他
A11: ='Table 1'!AO12 -> JS3140 | B11: =IF('Table 1'!AS12="","比重10:"&'Table 1'!AQ12&CHAR(10)&"比重7:其他","比重10:"&'Table 1'!AQ12&CHAR(10)&"比重7:"&'Table 1'!AR12&CHAR(10)&"比重5:"&"其他") -> 比重10:CHEM, ENG, ICT, MATH, M2, PHY 比重7:BIO, 中文, 通 比重5:其他 | C11: 比重10:CHEM, ENG, ICT, MATH, M2, PHY 比重7:BIO, 中文, 通 比重5:其他
A12: ='Table 1'!AO13 -> JS3150 | B12: =IF('Table 1'!AS13="","比重10:"&'Table 1'!AQ13&CHAR(10)&"比重7:其他","比重10:"&'Table 1'!AQ13&CHAR(10)&"比重7:"&'Table 1'!AR13&CHAR(10)&"比重5:"&"其他") -> 比重10:BIO, CHEM, MATH, M2, PHY 比重7:中文, ENG, 通 比重5:其他 | C12: 比重10:BIO, CHEM, MATH, M2, PHY 比重7:中文, ENG, 通 比重5:其他
... A31: ='Table 1'!AO32 -> JS3868 | B31: =IF('Table 1'!AS32="","比重10:"&'Table 1'!AQ32&CHAR(10)&"比重7:其他","比重10:"&'Table 1'!AQ32&CHAR(10)&"比重7:"&'Table 1'!AR32&CHAR(10)&"比重5:"&"其他") -> 比重10:BIO, BAFS, CHEM, ECON, ENG, ICT, MATH, M2, PHY 比重7:其他 | C31: 比重10:BIO, BAFS, CHEM, ECON, ENG, ICT, MATH, M2, PHY 比重7:其他
